Workbook

Sheet มกราคม69
A1: แร็คพวงมาลัย | I1: มกราคม.2569
A2: No. | B2: Parts | C2: รายการ | H2: 23.01 | I2: 26.01 | J2: 30.01 | L2: รวมเข้า | M2: 13.01 | N2: เหลือ | O2: 14.01 | P2: เหลือ | Q2: 15.01 | R2: เหลือ | S2: 16.01 | T2: เหลือ | U2: 18.01 | V2: เหลือ | W2: 19.01 | X2: เหลือ | Y2: 20.01 | Z2: เหลือ | AA2: 21.01 | AB2: เหลือ | AC2: 22.01 | AD2: เหลือ | AE2: 23.01 | AF2: เหลือ | AG2: 24.01 | AH2: เหลือ | AI2: 26.01 | AJ2: เหลือ | AK2: 27.01 | AL2: เหลือ | AM2: 28.01 | AN2: เหลือ | AO2: 29.01 | AP2: เหลือ | AQ2: 30.01 | AR2: เหลือ | AS2: 31.01 | AT2: เหลือ
A3: 1 | B3: RTTO7214 | C3: แร็คใหม่ OEM Toyota Alphard Vellfire ANH20 GGH20 ปี 08-14 | J3: 1 | L3: 3 | N3: =L3 -> 3 | P3: =N3-O3 -> 3 | R3: =P3-Q3 -> 3 | T3: =R3-S3 -> 3 | V3: =T3+U3 -> 3 | X3: =V3-W3 -> 3 | Z3: =X3-Y3 -> 3 | AB3: =Z3-AA3 -> 3 | AD3: =AB3-AC3 -> 3 | AF3: =AD3-AE3 -> 3 | AH3: =AF3-AG3 -> 3 | AJ3: =AH3-AI3 -> 3 | AL3: =AJ3-AK3 -> 3 | AN3: =AL3-AM3 -> 3 | AP3: =AN3-AO3 -> 3 | AR3: =AP3-AQ3 -> 3 | AT3: =AR3-AS3 -> 3
A4: 2 | B4: RTTO7216 | C4: แร็คใหม่ OEM Toyota Alphard Vellfire รุ่น 20 (08-16) | H4: 4 | J4: 4 | L4: =SUM(H4:K4) -> 8 | N4: =L4 -> 8 | P4: =N4-O4 -> 8 | R4: =P4-Q4 -> 8 | T4: =R4-S4 -> 8 | V4: =T4+U4 -> 8 | X4: =V4-W4 -> 8 | Z4: =X4-Y4 -> 8 | AB4: =Z4-AA4 -> 8 | AD4: =AB4-AC4 -> 8 | AE4: 1 | AF4: =AD4-AE4 -> 7 | AH4: =AF4-AG4 -> 7 | AJ4: =AH4-AI4 -> 7 | AL4: =AJ4-AK4 -> 7 | AN4: =AL4-AM4 -> 7 | AP4: =AN4-AO4 -> 7 | AR4: =AP4-AQ4 -> 7 | AT4: =AR4-AS4 -> 7
A5: 3 | B5: RTTO7213 | C5: แร็คใหม่ OEM Toyota Alphard Vellfire 2015up AGH3/AYH30 GGH3 | H5: 3 | J5: 2 | L5: =SUM(H5:K5) -> 5 | N5: =L5 -> 5 | P5: =N5-O5 -> 5 | R5: =P5-Q5 -> 5 | T5: =R5-S5 -> 5 | V5: =T5+U5 -> 5 | X5: =V5-W5 -> 5 | Z5: =X5-Y5 -> 5 | AB5: =Z5-AA5 -> 5 | AD5: =AB5-AC5 -> 5 | AF5: =AD5-AE5 -> 5 | AG5: 1 | AH5: =AF5-AG5 -> 4 | AJ5: =AH5-AI5 -> 4 | AL5: =AJ5-AK5 -> 4 | AN5: =AL5-AM5 -> 4 | AP5: =AN5-AO5 -> 4 | AR5: =AP5-AQ5 -> 4 | AT5: =AR5-AS5 -> 4
A6: 4 | B6: RTTO5218 | C6: แร็คใหม่ OEM Toyota Corola AT190/ST191 ปี 1992-1997 | H6: 2 | J6: 2 | L6: =SUM(H6:J6) -> 4 | N6: =L6 -> 4 | P6: =N6-O6 -> 4 | R6: =P6-Q6 -> 4 | T6: =R6-S6 -> 4 | V6: =T6+U6 -> 4 | X6: =V6-W6 -> 4 | Z6: =X6-Y6 -> 4 | AB6: =Z6-AA6 -> 4 | AD6: =AB6-AC6 -> 4 | AF6: =AD6-AE6 -> 4 | AH6: =AF6-AG6 -> 4 | AJ6: =AH6-AI6 -> 4 | AL6: =AJ6-AK6 -> 4 | AN6: =AL6-AM6 -> 4 | AP6: =AN6-AO6 -> 4 | AR6: =AP6-AQ6 -> 4 | AT6: =AR6-AS6 -> 4
A7: 5 | B7: RTTO5201 | C7: แร็คใหม่ OEM Toyota Corola AE100 AE111 AE112 1991-2000 | H7: 2 | J7: 2 | L7: =SUM(H7:J7) -> 4 | N7: =L7 -> 4 | P7: =N7-O7 -> 4 | R7: =P7-Q7 -> 4 | T7: =R7-S7 -> 4 | V7: =T7+U7 -> 4 | X7: =V7-W7 -> 4 | Z7: =X7-Y7 -> 4 | AB7: =Z7-AA7 -> 4 | AD7: =AB7-AC7 -> 4 | AF7: =AD7-AE7 -> 4 | AH7: =AF7-AG7 -> 4 | AJ7: =AH7-AI7 -> 4 | AL7: =AJ7-AK7 -> 4 | AN7: =AL7-AM7 -> 4 | AP7: =AN7-AO7 -> 4 | AR7: =AP7-AQ7 -> 4 | AT7: =AR7-AS7 -> 4
A8: 6 | B8: RTTO7212 | C8: แร็คใหม่ OEM Toyota CH-R 2018-up /Ty Corola Cross ปี 2020-up | H8: 2 | J8: 2 | L8: =SUM(H8:J8) -> 4 | N8: =L8 -> 4 | P8: =N8-O8 -> 4 | R8: =P8-Q8 -> 4 | T8: =R8-S8 -> 4 | V8: =T8+U8 -> 4 | X8: =V8-W8 -> 4 | Z8: =X8-Y8 -> 4 | AB8: =Z8-AA8 -> 4 | AD8: =AB8-AC8 -> 4 | AF8: =AD8-AE8 -> 4 | AH8: =AF8-AG8 -> 4 | AJ8: =AH8-AI8 -> 4 | AL8: =AJ8-AK8 -> 4 | AN8: =AL8-AM8 -> 4 | AP8: =AN8-AO8 -> 4 | AR8: =AP8-AQ8 -> 4 | AT8: =AR8-AS8 -> 4
A9: 7 | B9: RTTO5205-1 | C9: แร็คใหม่ OEM Toyota Commuter KDH200 Short หลังคาเตี้ย ปี 05-18 | H9: 1 | J9: 1 | L9: =SUM(H9:J9) -> 2 | N9: =L9 -> 2 | P9: =N9-O9 -> 2 | R9: =P9-Q9 -> 2 | T9: =R9-S9 -> 2 | V9: =T9+U9 -> 2 | X9: =V9-W9 -> 2 | Z9: =X9-Y9 -> 2 | AB9: =Z9-AA9 -> 2 | AD9: =AB9-AC9 -> 2 | AF9: =AD9-AE9 -> 2 | AH9: =AF9-AG9 -> 2 | AJ9: =AH9-AI9 -> 2 | AL9: =AJ9-AK9 -> 2 | AN9: =AL9-AM9 -> 2 | AP9: =AN9-AO9 -> 2 | AR9: =AP9-AQ9 -> 2 | AT9: =AR9-AS9 -> 2
A10: 8 | B10: RTTO5205 | C10: แร็คใหม่ OEM Toyota Commuter KDH220 หลังคาสูง ปี 05-19 | J10: 5 | L10: =SUM(H10:J10) -> 5 | N10: =L10 -> 5 | P10: =N10-O10 -> 5 | R10: =P10-Q10 -> 5 | T10: =R10-S10 -> 5 | V10: =T10+U10 -> 5 | X10: =V10-W10 -> 5 | Z10: =X10-Y10 -> 5 | AB10: =Z10-AA10 -> 5 | AD10: =AB10-AC10 -> 5 | AF10: =AD10-AE10 -> 5 | AH10: =AF10-AG10 -> 5 | AJ10: =AH10-AI10 -> 5 | AL10: =AJ10-AK10 -> 5 | AN10: =AL10-AM10 -> 5 | AP10: =AN10-AO10 -> 5 | AR10: =AP10-AQ10 -> 5 | AT10: =AR10-AS10 -> 5
A11: 9 | B11: RTTO5211 | C11: แร็คใหม่ OEM Toyota Hilux Revo 2WD ตัวเตี้ย Innova ปี 15-25 | L11: =SUM(H11:J11) -> 0 | N11: =L11 -> 0 | P11: =N11-O11 -> 0 | R11: =P11-Q11 -> 0 | T11: =R11-S11 -> 0 | V11: =T11+U11 -> 0 | X11: =V11-W11 -> 0 | Z11: =X11-Y11 -> 0 | AB11: =Z11-AA11 -> 0 | AD11: =AB11-AC11 -> 0 | AF11: =AD11-AE11 -> 0 | AH11: =AF11-AG11 -> 0 | AJ11: =AH11-AI11 -> 0 | AL11: =AJ11-AK11 -> 0 | AN11: =AL11-AM11 -> 0 | AP11: =AN11-AO11 -> 0 | AR11: =AP11-AQ11 -> 0 | AT11: =AR11-AS11 -> 0
A12: 10 | B12: RTTO5210 | C12: แร็คใหม่ OEM Toyota Hilux Revo 4WD ยกสูง Fortuner ปี 15-25 | L12: =SUM(H12:J12) -> 0 | N12: =L12 -> 0 | P12: =N12-O12 -> 0 | R12: =P12-Q12 -> 0 | T12: =R12-S12 -> 0 | V12: =T12+U12 -> 0 | X12: =V12-W12 -> 0 | Z12: =X12-Y12 -> 0 | AB12: =Z12-AA12 -> 0 | AD12: =AB12-AC12 -> 0 | AF12: =AD12-AE12 -> 0 | AH12: =AF12-AG12 -> 0 | AJ12: =AH12-AI12 -> 0 | AL12: =AJ12-AK12 -> 0 | AN12: =AL12-AM12 -> 0 | AP12: =AN12-AO12 -> 0 | AR12: =AP12-AQ12 -> 0 | AT12: =AR12-AS12 -> 0
A13: 11 | B13: RTTO5213 | C13: แร็คใหม่ OEM Toyota Camry ACV 30 ปี 02-06 | H13: 6 | J13: 6 | L13: =SUM(H13:J13) -> 12 | N13: =L13 -> 12 | P13: =N13-O13 -> 12 | R13: =P13-Q13 -> 12 | T13: =R13-S13 -> 12 | V13: =T13+U13 -> 12 | X13: =V13-W13 -> 12 | Z13: =X13-Y13 -> 12 | AB13: =Z13-AA13 -> 12 | AD13: =AB13-AC13 -> 12 | AF13: =AD13-AE13 -> 12 | AH13: =AF13-AG13 -> 12 | AJ13: =AH13-AI13 -> 12 | AL13: =AJ13-AK13 -> 12 | AN13: =AL13-AM13 -> 12 | AP13: =AN13-AO13 -> 12 | AR13: =AP13-AQ13 -> 12 | AT13: =AR13-AS13 -> 12
A14: 12 | B14: RTTO5214 | C14: แร็คใหม่ OEM Toyota Camry ACV 40 ปี 08-2012 เครื่อง 1AZ-2Z | H14: 2 | J14: 2 | L14: =SUM(H14:J14) -> 4 | N14: =L14 -> 4 | P14: =N14-O14 -> 4 | R14: =P14-Q14 -> 4 | T14: =R14-S14 -> 4 | V14: =T14+U14 -> 4 | X14: =V14-W14 -> 4 | Z14: =X14-Y14 -> 4 | AB14: =Z14-AA14 -> 4 | AD14: =AB14-AC14 -> 4 | AF14: =AD14-AE14 -> 4 | AH14: =AF14-AG14 -> 4 | AJ14: =AH14-AI14 -> 4 | AL14: =AJ14-AK14 -> 4 | AN14: =AL14-AM14 -> 4 | AP14: =AN14-AO14 -> 4 | AR14: =AP14-AQ14 -> 4 | AS14: 1 | AT14: =AR14-AS14 -> 3
A15: 13 | B15: RTTO7209 | C15: แร็คใหม่ OEM Toyota Camry ACV 50 ACV 51 ปี (12-18) | H15: 4 | L15: =SUM(H15:J15) -> 4 | N15: =L15 -> 4 | P15: =N15-O15 -> 4 | R15: =P15-Q15 -> 4 | T15: =R15-S15 -> 4 | V15: =T15+U15 -> 4 | X15: =V15-W15 -> 4 | Z15: =X15-Y15 -> 4 | AB15: =Z15-AA15 -> 4 | AD15: =AB15-AC15 -> 4 | AF15: =AD15-AE15 -> 4 | AH15: =AF15-AG15 -> 4 | AJ15: =AH15-AI15 -> 4 | AL15: =AJ15-AK15 -> 4 | AN15: =AL15-AM15 -> 4 | AP15: =AN15-AO15 -> 4 | AR15: =AP15-AQ15 -> 4 | AT15: =AR15-AS15 -> 4
A16: 14 | B16: RTTO5203 | C16: แร็คใหม่ OEM Toyota Altis, Limo ปี 2001-2007 | H16: 6 | J16: 5 | L16: =SUM(H16:J16) -> 11 | N16: =L16 -> 11 | P16: =N16-O16 -> 11 | R16: =P16-Q16 -> 11 | T16: =R16-S16 -> 11 | V16: =T16+U16 -> 11 | X16: =V16-W16 -> 11 | Z16: =X16-Y16 -> 11 | AB16: =Z16-AA16 -> 11 | AD16: =AB16-AC16 -> 11 | AF16: =AD16-AE16 -> 11 | AH16: =AF16-AG16 -> 11 | AJ16: =AH16-AI16 -> 11 | AL16: =AJ16-AK16 -> 11 | AN16: =AL16-AM16 -> 11 | AP16: =AN16-AO16 -> 11 | AR16: =AP16-AQ16 -> 11 | AT16: =AR16-AS16 -> 11
A17: 15 | B17: RTTO7202 | C17: แร็คใหม่ OEM Toyota Altis หน้าแบน เครื่อง 3ZZ 2ZZ ปี 08-12กระบอกไม่มีลายเหลี่ยม | H17: 6 | J17: 5 | L17: =SUM(H17:J17) -> 11 | N17: =L17 -> 11 | P17: =N17-O17 -> 11 | R17: =P17-Q17 -> 11 | T17: =R17-S17 -> 11 | V17: =T17+U17 -> 11 | X17: =V17-W17 -> 11 | Z17: =X17-Y17 -> 11 | AB17: =Z17-AA17 -> 11 | AD17: =AB17-AC17 -> 11 | AF17: =AD17-AE17 -> 11 | AG17: 1 | AH17: =AF17-AG17 -> 10 | AJ17: =AH17-AI17 -> 10 | AL17: =AJ17-AK17 -> 10 | AN17: =AL17-AM17 -> 10 | AP17: =AN17-AO17 -> 10 | AR17: =AP17-AQ17 -> 10 | AT17: =AR17-AS17 -> 10
A18: 16 | B18: RTTO7203 | C18: แร็คใหม่ OEM Toyota Altis ปี 13-19 | H18: 4 | J18: 3 | L18: =SUM(H18:J18) -> 7 | N18: =L18 -> 7 | P18: =N18-O18 -> 7 | R18: =P18-Q18 -> 7 | T18: =R18-S18 -> 7 | V18: =T18+U18 -> 7 | X18: =V18-W18 -> 7 | Z18: =X18-Y18 -> 7 | AB18: =Z18-AA18 -> 7 | AD18: =AB18-AC18 -> 7 | AE18: 1 | AF18: =AD18-AE18 -> 6 | AH18: =AF18-AG18 -> 6 | AJ18: =AH18-AI18 -> 6 | AL18: =AJ18-AK18 -> 6 | AN18: =AL18-AM18 -> 6 | AP18: =AN18-AO18 -> 6 | AR18: =AP18-AQ18 -> 6 | AT18: =AR18-AS18 -> 6
A19: 17 | B19: RTTO7208 | C19: แร็คใหม่ OEM Toyota Altis ปี 2019-ป้จจุบัน | H19: 1 | J19: 1 | L19: =SUM(H19:J19) -> 2 | N19: =L19 -> 2 | P19: =N19-O19 -> 2 | R19: =P19-Q19 -> 2 | T19: =R19-S19 -> 2 | V19: =T19+U19 -> 2 | X19: =V19-W19 -> 2 | Z19: =X19-Y19 -> 2 | AB19: =Z19-AA19 -> 2 | AD19: =AB19-AC19 -> 2 | AF19: =AD19-AE19 -> 2 | AH19: =AF19-AG19 -> 2 | AJ19: =AH19-AI19 -> 2 | AL19: =AJ19-AK19 -> 2 | AN19: =AL19-AM19 -> 2 | AP19: =AN19-AO19 -> 2 | AR19: =AP19-AQ19 -> 2 | AT19: =AR19-AS19 -> 2
A20: 18 | B20: RTTO5209 | C20: แร็คใหม่ OEM Toyota Vios ปี 02-07 | H20: 2 | J20: 5 | L20: =SUM(H20:J20) -> 7 | N20: =L20 -> 7 | P20: =N20-O20 -> 7 | R20: =P20-Q20 -> 7 | T20: =R20-S20 -> 7 | V20: =T20+U20 -> 7 | X20: =V20-W20 -> 7 | Z20: =X20-Y20 -> 7 | AB20: =Z20-AA20 -> 7 | AD20: =AB20-AC20 -> 7 | AF20: =AD20-AE20 -> 7 | AH20: =AF20-AG20 -> 7 | AJ20: =AH20-AI20 -> 7 | AL20: =AJ20-AK20 -> 7 | AN20: =AL20-AM20 -> 7 | AP20: =AN20-AO20 -> 7 | AQ20: 1 | AR20: =AP20-AQ20 -> 6 | AT20: =AR20-AS20 -> 6
A21: 19 | B21: RTTO7201 | C21: แร็คใหม่ OEM Toyota Vios ปี 07-13 /Yaris 1.5 ปี 08-13 | H21: 7 | J21: 5 | L21: =SUM(H21:J21) -> 12 | N21: =L21 -> 12 | P21: =N21-O21 -> 12 | R21: =P21-Q21 -> 12 | T21: =R21-S21 -> 12 | V21: =T21+U21 -> 12 | X21: =V21-W21 -> 12 | Z21: =X21-Y21 -> 12 | AB21: =Z21-AA21 -> 12 | AD21: =AB21-AC21 -> 12 | AE21: 1 | AF21: =AD21-AE21 -> 11 | AH21: =AF21-AG21 -> 11 | AI21: 1 | AJ21: =AH21-AI21 -> 10 | AL21: =AJ21-AK21 -> 10 | AN21: =AL21-AM21 -> 10 | AP21: =AN21-AO21 -> 10 | AR21: =AP21-AQ21 -> 10 | AT21: =AR21-AS21 -> 10
A22: 20 | B22: RTTO7204 | C22: แร็คใหม่ OEM Toyota Vios /Yaris 1.2 ปี 13-22 | H22: 6 | J22: 2 | L22: =SUM(H22:J22) -> 8 | N22: =L22 -> 8 | P22: =N22-O22 -> 8 | R22: =P22-Q22 -> 8 | T22: =R22-S22 -> 8 | V22: =T22+U22 -> 8 | X22: =V22-W22 -> 8 | Z22: =X22-Y22 -> 8 | AB22: =Z22-AA22 -> 8 | AD22: =AB22-AC22 -> 8 | AE22: 1 | AF22: =AD22-AE22 -> 7 | AH22: =AF22-AG22 -> 7 | AJ22: =AH22-AI22 -> 7 | AL22: =AJ22-AK22 -> 7 | AM22: 2 | AN22: =AL22-AM22 -> 5 | AP22: =AN22-AO22 -> 5 | AR22: =AP22-AQ22 -> 5 | AT22: =AR22-AS22 -> 5
A23: 21 | B23: RTTO7205 | C23: แร็คใหม่ OEM Toyota Prius (2009-2016) | J23: 4 | L23: =SUM(H23:J23) -> 4 | N23: =L23 -> 4
A24: 22 | B24: RTT05205 | C24: แร็คใหม่ OEM Toyota Commuter KDH220 หลังคาสูง ปี 05-18 | H24: 6 | L24: =SUM(H24:J24) -> 6 | N24: =L24 -> 6 | P24: =N24-O24 -> 6 | R24: =P24-Q24 -> 6 | T24: =R24-S24 -> 6 | V24: =T24+U24 -> 6 | X24: =V24-W24 -> 6 | Z24: =X24-Y24 -> 6 | AB24: =Z24-AA24 -> 6 | AD24: =AB24-AC24 -> 6 | AF24: =AD24-AE24 -> 6 | AH24: =AF24-AG24 -> 6 | AJ24: =AH24-AI24 -> 6 | AL24: =AJ24-AK24 -> 6 | AN24: =AL24-AM24 -> 6 | AP24: =AN24-AO24 -> 6 | AR24: =AP24-AQ24 -> 6 | AT24: =AR24-AS24 -> 6
A25: 23 | B25: RTTO5233 | C25: แร็คใหม่ OEM Toyota Hiace Commuter Granvia ปี 2020 | J25: 1 | L25: =SUM(H25:J25) -> 1 | N25: =L25 -> 1 | P25: =N25-O25 -> 1 | R25: =P25-Q25 -> 1 | T25: =R25-S25 -> 1 | V25: =T25+U25 -> 1 | X25: =V25-W25 -> 1 | Z25: =X25-Y25 -> 1 | AB25: =Z25-AA25 -> 1 | AD25: =AB25-AC25 -> 1 | AF25: =AD25-AE25 -> 1 | AH25: =AF25-AG25 -> 1 | AJ25: =AH25-AI25 -> 1 | AL25: =AJ25-AK25 -> 1 | AN25: =AL25-AM25 -> 1 | AP25: =AN25-AO25 -> 1 | AR25: =AP25-AQ25 -> 1 | AT25: =AR25-AS25 -> 1
A26: 24 | B26: RTTO5204 | C26: แร็คใหม่ OEM Toyota Hiace LH125/LH112 ปี 1992-2004 ตู้หัวจรด | H26: 1 | J26: 1 | L26: =SUM(H26:J26) -> 2 | N26: =L26 -> 2 | P26: =N26-O26 -> 2 | R26: =P26-Q26 -> 2 | T26: =R26-S26 -> 2 | V26: =T26+U26 -> 2 | X26: =V26-W26 -> 2 | Z26: =X26-Y26 -> 2 | AB26: =Z26-AA26 -> 2 | AD26: =AB26-AC26 -> 2 | AF26: =AD26-AE26 -> 2 | AH26: =AF26-AG26 -> 2 | AJ26: =AH26-AI26 -> 2 | AL26: =AJ26-AK26 -> 2 | AN26: =AL26-AM26 -> 2 | AP26: =AN26-AO26 -> 2 | AR26: =AP26-AQ26 -> 2 | AT26: =AR26-AS26 -> 2
A27: 25 | B27: RTTO5211 | C27: แร็คใหม่ OEM Toyota Revo 2WD/ Innova ปี 15-ปัจจุบัน | H27: 2 | L27: =SUM(H27:J27) -> 2 | N27: =L27 -> 2 | P27: =N27-O27 -> 2 | R27: =P27-Q27 -> 2 | T27: =R27-S27 -> 2 | V27: =T27+U27 -> 2 | X27: =V27-W27 -> 2 | Z27: =X27-Y27 -> 2 | AB27: =Z27-AA27 -> 2 | AD27: =AB27-AC27 -> 2 | AF27: =AD27-AE27 -> 2 | AH27: =AF27-AG27 -> 2 | AJ27: =AH27-AI27 -> 2 | AL27: =AJ27-AK27 -> 2 | AN27: =AL27-AM27 -> 2 | AP27: =AN27-AO27 -> 2 | AR27: =AP27-AQ27 -> 2 | AT27: =AR27-AS27 -> 2
A28: 26 | B28: RTTO5210 | C28: แร็คใหม่ OEM Toyota Revo 4WD/ Fortuner ปี 15-ปัจจุบัน | H28: 1 | J28: 1 | L28: =SUM(H28:J28) -> 2 | N28: =L28 -> 2 | P28: =N28-O28 -> 2 | R28: =P28-Q28 -> 2 | T28: =R28-S28 -> 2 | V28: =T28+U28 -> 2 | X28: =V28-W28 -> 2 | Z28: =X28-Y28 -> 2 | AB28: =Z28-AA28 -> 2 | AD28: =AB28-AC28 -> 2 | AF28: =AD28-AE28 -> 2 | AH28: =AF28-AG28 -> 2 | AJ28: =AH28-AI28 -> 2 | AL28: =AJ28-AK28 -> 2 | AN28: =AL28-AM28 -> 2 | AP28: =AN28-AO28 -> 2 | AQ28: 1 | AR28: =AP28-AQ28 -> 1 | AT28: =AR28-AS28 -> 1
A29: 27 | B29: RTTO7225 | C29: แร็คใหม่ OEM Toyota RX270/350/450H/AGL10/GGL1 ปี 08-15 | H29: 2 | J29: 2 | L29: =SUM(H29:J29) -> 4 | N29: =L29 -> 4 | P29: =N29-O29 -> 4 | R29: =P29-Q29 -> 4 | T29: =R29-S29 -> 4 | V29: =T29+U29 -> 4 | X29: =V29-W29 -> 4 | Z29: =X29-Y29 -> 4 | AB29: =Z29-AA29 -> 4 | AD29: =AB29-AC29 -> 4 | AF29: =AD29-AE29 -> 4 | AH29: =AF29-AG29 -> 4 | AJ29: =AH29-AI29 -> 4 | AL29: =AJ29-AK29 -> 4 | AN29: =AL29-AM29 -> 4 | AP29: =AN29-AO29 -> 4 | AR29: =AP29-AQ29 -> 4 | AT29: =AR29-AS29 -> 4
A30: 28 | B30: RTTO5206 | C30: แร็คใหม่ OEM Toyota Vigo 2WD Innova ปี 2004-2015 | H30: 5 | L30: =SUM(H30:J30) -> 5 | N30: =L30 -> 5 | P30: =N30-O30 -> 5 | R30: =P30-Q30 -> 5 | T30: =R30-S30 -> 5 | V30: =T30+U30 -> 5 | X30: =V30-W30 -> 5 | Z30: =X30-Y30 -> 5 | AB30: =Z30-AA30 -> 5 | AD30: =AB30-AC30 -> 5 | AF30: =AD30-AE30 -> 5 | AH30: =AF30-AG30 -> 5 | AJ30: =AH30-AI30 -> 5 | AL30: =AJ30-AK30 -> 5 | AN30: =AL30-AM30 -> 5 | AP30: =AN30-AO30 -> 5 | AR30: =AP30-AQ30 -> 5 | AT30: =AR30-AS30 -> 5
A31: 29 | B31: RTTO5207 | C31: แร็คใหม่ OEM Toyota Vigo 4WD ยกสูง Fortuner ปี 04-15 | H31: 5 | J31: 5 | L31: =SUM(H31:J31) -> 10 | N31: =L31 -> 10 | P31: =N31-O31 -> 10 | R31: =P31-Q31 -> 10 | T31: =R31-S31 -> 10 | V31: =T31+U31 -> 10 | X31: =V31-W31 -> 10 | Z31: =X31-Y31 -> 10 | AB31: =Z31-AA31 -> 10 | AD31: =AB31-AC31 -> 10 | AF31: =AD31-AE31 -> 10 | AH31: =AF31-AG31 -> 10 | AJ31: =AH31-AI31 -> 10 | AL31: =AJ31-AK31 -> 10 | AN31: =AL31-AM31 -> 10 | AP31: =AN31-AO31 -> 10 | AR31: =AP31-AQ31 -> 10 | AT31: =AR31-AS31 -> 10
A32: 30
A33: 31 | B33: RTHO5202 | C33: แร็คใหม่ OEM Honda Accord G-7 ปี 2003-2007 ปลาวาฬ | H33: 2 | J33: 2 | L33: =SUM(H33:J33) -> 4 | N33: =L33 -> 4 | P33: =N33-O33 -> 4 | R33: =P33-Q33 -> 4 | T33: =R33-S33 -> 4 | V33: =T33+U33 -> 4 | X33: =V33-W33 -> 4 | Z33: =X33-Y33 -> 4 | AB33: =Z33-AA33 -> 4 | AD33: =AB33-AC33 -> 4 | AF33: =AD33-AE33 -> 4 | AH33: =AF33-AG33 -> 4 | AJ33: =AH33-AI33 -> 4 | AL33: =AJ33-AK33 -> 4 | AN33: =AL33-AM33 -> 4 | AP33: =AN33-AO33 -> 4 | AR33: =AP33-AQ33 -> 4 | AT33: =AR33-AS33 -> 4
A34: 32 | B34: RTHO5211 | C34: แร็คใหม่ OEM Honda Accord G-8 ปี 2008-2012 | H34: 4 | J34: 4 | L34: =SUM(H34:J34) -> 8 | N34: =L34 -> 8 | P34: =N34-O34 -> 8 | R34: =P34-Q34 -> 8 | T34: =R34-S34 -> 8 | V34: =T34+U34 -> 8 | X34: =V34-W34 -> 8 | Z34: =X34-Y34 -> 8 | AB34: =Z34-AA34 -> 8 | AD34: =AB34-AC34 -> 8 | AF34: =AD34-AE34 -> 8 | AH34: =AF34-AG34 -> 8 | AJ34: =AH34-AI34 -> 8 | AL34: =AJ34-AK34 -> 8 | AN34: =AL34-AM34 -> 8 | AP34: =AN34-AO34 -> 8 | AR34: =AP34-AQ34 -> 8 | AT34: =AR34-AS34 -> 8
A35: 33 | B35: RTHO5207 | C35: แร็คใหม่ OEM Honda CR-V G1 ปี 1996-2001 | H35: 2 | J35: 2 | L35: =SUM(H35:J35) -> 4 | N35: =L35 -> 4 | P35: =N35-O35 -> 4 | R35: =P35-Q35 -> 4 | T35: =R35-S35 -> 4 | V35: =T35+U35 -> 4 | X35: =V35-W35 -> 4 | Z35: =X35-Y35 -> 4 | AB35: =Z35-AA35 -> 4 | AD35: =AB35-AC35 -> 4 | AF35: =AD35-AE35 -> 4 | AH35: =AF35-AG35 -> 4 | AJ35: =AH35-AI35 -> 4 | AL35: =AJ35-AK35 -> 4 | AN35: =AL35-AM35 -> 4 | AP35: =AN35-AO35 -> 4 | AR35: =AP35-AQ35 -> 4 | AT35: =AR35-AS35 -> 4
A36: 34 | B36: RTHO5205 | C36: แร็คใหม่ OEM Honda CR-V G2 ปี 2002-2006 | H36: 2 | J36: 2 | L36: =SUM(H36:J36) -> 4 | N36: =L36 -> 4 | P36: =N36-O36 -> 4 | R36: =P36-Q36 -> 4 | T36: =R36-S36 -> 4 | V36: =T36+U36 -> 4 | X36: =V36-W36 -> 4 | Z36: =X36-Y36 -> 4 | AB36: =Z36-AA36 -> 4 | AD36: =AB36-AC36 -> 4 | AF36: =AD36-AE36 -> 4 | AH36: =AF36-AG36 -> 4 | AJ36: =AH36-AI36 -> 4 | AL36: =AJ36-AK36 -> 4 | AN36: =AL36-AM36 -> 4 | AP36: =AN36-AO36 -> 4 | AR36: =AP36-AQ36 -> 4 | AT36: =AR36-AS36 -> 4
A37: 35 | B37: RTHO5204 | C37: แร็คใหม่ OEM Honda Civic FD (น้้ามัน) ปี 06-11 | H37: 6 | J37: 6 | L37: =SUM(H37:J37) -> 12 | N37: =L37 -> 12 | P37: =N37-O37 -> 12 | R37: =P37-Q37 -> 12 | T37: =R37-S37 -> 12 | V37: =T37+U37 -> 12 | X37: =V37-W37 -> 12 | Z37: =X37-Y37 -> 12 | AB37: =Z37-AA37 -> 12 | AD37: =AB37-AC37 -> 12 | AF37: =AD37-AE37 -> 12 | AH37: =AF37-AG37 -> 12 | AJ37: =AH37-AI37 -> 12 | AL37: =AJ37-AK37 -> 12 | AN37: =AL37-AM37 -> 12 | AP37: =AN37-AO37 -> 12 | AR37: =AP37-AQ37 -> 12 | AT37: =AR37-AS37 -> 12
A38: 36 | B38: RTHO5206 | C38: แร็คใหม่ OEM Honda Civic Dimension ES ปี 2001-2005 | H38: 2 | J38: 2 | L38: =SUM(H38:J38) -> 4 | N38: =L38 -> 4 | P38: =N38-O38 -> 4 | R38: =P38-Q38 -> 4 | T38: =R38-S38 -> 4 | V38: =T38+U38 -> 4 | X38: =V38-W38 -> 4 | Z38: =X38-Y38 -> 4 | AB38: =Z38-AA38 -> 4 | AD38: =AB38-AC38 -> 4 | AF38: =AD38-AE38 -> 4 | AH38: =AF38-AG38 -> 4 | AJ38: =AH38-AI38 -> 4 | AL38: =AJ38-AK38 -> 4 | AN38: =AL38-AM38 -> 4 | AP38: =AN38-AO38 -> 4 | AR38: =AP38-AQ38 -> 4 | AT38: =AR38-AS38 -> 4
A39: 37 | B39: RTHO7203 | C39: แร็คใหม่ OEM Honda HR-V 2WD ปี 2015-2021 | H39: 2 | L39: =SUM(H39:J39) -> 2 | N39: =L39 -> 2 | P39: =N39-O39 -> 2 | R39: =P39-Q39 -> 2 | T39: =R39-S39 -> 2 | V39: =T39+U39 -> 2 | X39: =V39-W39 -> 2 | Z39: =X39-Y39 -> 2 | AB39: =Z39-AA39 -> 2 | AD39: =AB39-AC39 -> 2 | AF39: =AD39-AE39 -> 2 | AH39: =AF39-AG39 -> 2 | AJ39: =AH39-AI39 -> 2 | AL39: =AJ39-AK39 -> 2 | AN39: =AL39-AM39 -> 2 | AP39: =AN39-AO39 -> 2 | AQ39: 1 | AR39: =AP39-AQ39 -> 1 | AT39: =AR39-AS39 -> 1
A40: 38 | B40: RTHO5203 | C40: แร็คใหม่ OEM Honda City Type Z ปี 1995-2002 | H40: 2 | J40: 2 | L40: =SUM(H40:J40) -> 4 | N40: =L40 -> 4 | P40: =N40-O40 -> 4 | R40: =P40-Q40 -> 4 | T40: =R40-S40 -> 4 | V40: =T40+U40 -> 4 | X40: =V40-W40 -> 4 | Z40: =X40-Y40 -> 4 | AB40: =Z40-AA40 -> 4 | AD40: =AB40-AC40 -> 4 | AF40: =AD40-AE40 -> 4 | AH40: =AF40-AG40 -> 4 | AJ40: =AH40-AI40 -> 4 | AL40: =AJ40-AK40 -> 4 | AN40: =AL40-AM40 -> 4 | AP40: =AN40-AO40 -> 4 | AR40: =AP40-AQ40 -> 4 | AT40: =AR40-AS40 -> 4
...

Sheet กุมภาพันธ์69
A1: แร็คพวงมาลัย | L1: กุมภาพันธ์.2569 | BT1: วานับวท.11/2
A2: No. | B2: Parts | C2: รายการ | K2: 3.02 | L2: 5.02 | M2: 11.02 | O2: รวมเข้า | P2: 1.02 | Q2: เหลือ | R2: 2.02 | S2: เหลือ | T2: 3.02 | U2: เหลือ | V2: 4.02 | W2: เหลือ | X2: 5.02 | Y2: เหลือ | Z2: 6.02 | AA2: เหลือ | AB2: 7.02 | AC2: เหลือ | AD2: 8.02 | AE2: เหลือ | AF2: 9.02 | AG2: เหลือ | AH2: 10.02 | AI2: เหลือ | AJ2: 11.02 | AK2: เหลือ | AL2: 12.02 | AM2: เหลือ | AN2: 13.02 | AO2: เหลือ | AP2: 14.02 | AQ2: เหลือ | AR2: 15.02 | AS2: เหลือ | AT2: 16.02 | AU2: เหลือ | AV2: 17.02 | AW2: เหลือ | AX2: 18.02 | AY2: เหลือ | AZ2: 19.02 | BA2: เหลือ | BB2: 20.02 | BC2: เหลือ | BD2: 21.02 | BE2: เหลือ | BF2: 22.02 | BG2: เหลือ | BH2: 23.02 | BI2: เหลือ | BJ2: 24.02 | BK2: เหลือ | BL2: 25.02 | BM2: เหลือ | BN2: 26.02 | BO2: เหลือ | BP2: 27.02 | BQ2: เหลือ | BR2: 28.02 | BS2: เหลือ | BT2: เหลือ
A3: 1 | B3: RTTO7214 | C3: แร็คใหม่ OEM Toyota Alphard Vellfire ANH20 GGH20 ปี 08-14 | O3: =SUM(K3:N3) -> 0 | Q3: =มกราคม69!AT3+O3 -> 3 | S3: =Q3-R3 -> 3 | U3: =S3-T3 -> 3 | W3: =U3-V3 -> 3 | Y3: =W3-X3 -> 3 | AA3: =Y3-Z3 -> 3 | AC3: =AA3+AB3 -> 3 | AE3: =AC3-AD3 -> 3 | AG3: =AE3-AF3 -> 3 | AI3: =AG3-AH3 -> 3 | AK3: =AI3-AJ3 -> 3 | AM3: =AK3-AL3 -> 3 | AO3: =AM3-AN3 -> 3 | AQ3: =AO3-AP3 -> 3 | AS3: =AQ3-AR3 -> 3 | AU3: =AS3-AT3 -> 3 | AW3: =AU3-AV3 -> 3 | AY3: =AW3-AX3 -> 3 | BA3: =AY3-AZ3 -> 3 | BC3: =BA3-BB3 -> 3 | BE3: =BC3-BD3 -> 3 | BG3: =BE3-BF3 -> 3 | BI3: =BG3-BH3 -> 3 | BK3: =BI3-BJ3 -> 3 | BM3: =BK3-BL3 -> 3 | BO3: =BM3-BN3 -> 3 | BQ3: =BO3-BP3 -> 3 | BS3: =BQ3-BR3 -> 3 | BT3: 1
A4: 2 | B4: RTTO7216 | C4: แร็คใหม่ OEM Toyota Alphard Vellfire รุ่น 20 (08-16) | K4: 2 | O4: =SUM(K4:N4) -> 2 | Q4: =มกราคม69!AT4+O4 -> 9 | S4: =Q4-R4 -> 9 | U4: =S4-T4 -> 9 | BC4: =BA4-BB4 -> 0 | BE4: =BC4-BD4 -> 0 | BG4: =BE4-BF4 -> 0 | BI4: =BG4-BH4 -> 0 | BK4: =BI4-BJ4 -> 0 | BM4: =BK4-BL4 -> 0 | BO4: =BM4-BN4 -> 0 | BQ4: =BO4-BP4 -> 0 | BS4: =BQ4-BR4 -> 0 | BT4: 6
A5: 3 | B5: RTTO7213 | C5: แร็คใหม่ OEM Toyota Alphard Vellfire 2015up AGH3/AYH30 GGH3 | K5: 2 | O5: =SUM(K5:N5) -> 2 | Q5: =มกราคม69!AT5+O5 -> 6 | S5: =Q5-R5 -> 6 | U5: =S5-T5 -> 6 | W5: =U5-V5 -> 6 | Y5: =W5-X5 -> 6 | AA5: =Y5-Z5 -> 6 | AC5: =AA5+AB5 -> 6 | AE5: =AC5-AD5 -> 6 | AG5: =AE5-AF5 -> 6 | AI5: =AG5-AH5 -> 6 | AK5: =AI5-AJ5 -> 6 | AM5: =AK5-AL5 -> 6 | AO5: =AM5-AN5 -> 6 | AQ5: =AO5-AP5 -> 6 | AS5: =AQ5-AR5 -> 6 | AU5: =AS5-AT5 -> 6 | AW5: =AU5-AV5 -> 6 | AY5: =AW5-AX5 -> 6 | BA5: =AY5-AZ5 -> 6 | BC5: =BA5-BB5 -> 6 | BE5: =BC5-BD5 -> 6 | BG5: =BE5-BF5 -> 6 | BI5: =BG5-BH5 -> 6 | BK5: =BI5-BJ5 -> 6 | BM5: =BK5-BL5 -> 6 | BO5: =BM5-BN5 -> 6 | BQ5: =BO5-BP5 -> 6 | BS5: =BQ5-BR5 -> 6 | BT5: 4
A6: 4 | B6: RTTO5218 | C6: แร็คใหม่ OEM Toyota Corola AT190/ST191 ปี 1992-1997 | O6: =SUM(K6:N6) -> 0 | Q6: =มกราคม69!AT6+O6 -> 4 | S6: =Q6-R6 -> 4 | U6: =S6-T6 -> 4 | BC6: =BA6-BB6 -> 0 | BE6: =BC6-BD6 -> 0 | BG6: =BE6-BF6 -> 0 | BI6: =BG6-BH6 -> 0 | BK6: =BI6-BJ6 -> 0 | BM6: =BK6-BL6 -> 0 | BO6: =BM6-BN6 -> 0 | BQ6: =BO6-BP6 -> 0 | BS6: =BQ6-BR6 -> 0 | BT6: 2
A7: 5 | B7: RTTO5201 | C7: แร็คใหม่ OEM Toyota Corola AE100 AE111 AE112 1991-2000 | O7: =SUM(K7:N7) -> 0 | Q7: =มกราคม69!AT7+O7 -> 4 | S7: =Q7-R7 -> 4 | U7: =S7-T7 -> 4 | W7: =U7-V7 -> 4 | Y7: =W7-X7 -> 4 | AA7: =Y7-Z7 -> 4 | AC7: =AA7+AB7 -> 4 | AE7: =AC7-AD7 -> 4 | AG7: =AE7-AF7 -> 4 | AI7: =AG7-AH7 -> 4 | AK7: =AI7-AJ7 -> 4 | AM7: =AK7-AL7 -> 4 | AO7: =AM7-AN7 -> 4 | AQ7: =AO7-AP7 -> 4 | AS7: =AQ7-AR7 -> 4 | AU7: =AS7-AT7 -> 4 | AW7: =AU7-AV7 -> 4 | AY7: =AW7-AX7 -> 4 | BA7: =AY7-AZ7 -> 4 | BC7: =BA7-BB7 -> 4 | BE7: =BC7-BD7 -> 4 | BG7: =BE7-BF7 -> 4 | BI7: =BG7-BH7 -> 4 | BK7: =BI7-BJ7 -> 4 | BM7: =BK7-BL7 -> 4 | BO7: =BM7-BN7 -> 4 | BQ7: =BO7-BP7 -> 4 | BS7: =BQ7-BR7 -> 4 | BT7: 2
A8: 6 | B8: RTTO7212 | C8: แร็คใหม่ OEM Toyota CH-R 2018-up /Ty Corola Cross ปี 2020-up | O8: =SUM(K8:N8) -> 0 | Q8: =มกราคม69!AT8+O8 -> 4 | S8: =Q8-R8 -> 4 | U8: =S8-T8 -> 4 | V8: 1 | AH8: 1 | BC8: =BA8-BB8 -> 0 | BE8: =BC8-BD8 -> 0 | BG8: =BE8-BF8 -> 0 | BI8: =BG8-BH8 -> 0 | BK8: =BI8-BJ8 -> 0 | BM8: =BK8-BL8 -> 0 | BO8: =BM8-BN8 -> 0 | BQ8: =BO8-BP8 -> 0 | BS8: =BQ8-BR8 -> 0 | BT8: 1
A9: 7 | B9: RTTO5205-1 | C9: แร็คใหม่ OEM Toyota Commuter KDH200 Short หลังคาเตี้ย ปี 05-18 | O9: =SUM(K9:N9) -> 0 | Q9: =มกราคม69!AT9+O9 -> 2 | S9: =Q9-R9 -> 2 | U9: =S9-T9 -> 2 | W9: =U9-V9 -> 2 | Y9: =W9-X9 -> 2 | AA9: =Y9-Z9 -> 2 | AC9: =AA9+AB9 -> 2 | AE9: =AC9-AD9 -> 2 | AG9: =AE9-AF9 -> 2 | AI9: =AG9-AH9 -> 2 | AK9: =AI9-AJ9 -> 2 | AM9: =AK9-AL9 -> 2 | AO9: =AM9-AN9 -> 2 | AQ9: =AO9-AP9 -> 2 | AS9: =AQ9-AR9 -> 2 | AU9: =AS9-AT9 -> 2 | AW9: =AU9-AV9 -> 2 | AY9: =AW9-AX9 -> 2 | BA9: =AY9-AZ9 -> 2 | BC9: =BA9-BB9 -> 2 | BE9: =BC9-BD9 -> 2 | BG9: =BE9-BF9 -> 2 | BI9: =BG9-BH9 -> 2 | BK9: =BI9-BJ9 -> 2 | BM9: =BK9-BL9 -> 2 | BO9: =BM9-BN9 -> 2 | BQ9: =BO9-BP9 -> 2 | BS9: =BQ9-BR9 -> 2 | BT9: 1
A10: 8 | B10: RTTO5205 | C10: แร็คใหม่ OEM Toyota Commuter KDH220 หลังคาสูง ปี 05-19 | O10: =SUM(K10:N10) -> 0 | Q10: =มกราคม69!AT10+O10 -> 5 | S10: =Q10-R10 -> 5 | U10: =S10-T10 -> 5 | W10: =U10-V10 -> 5 | Y10: =W10-X10 -> 5 | Z10: 1 | AA10: =Y10-Z10 -> 4 | AC10: =AA10+AB10 -> 4 | AE10: =AC10-AD10 -> 4 | AG10: =AE10-AF10 -> 4 | AI10: =AG10-AH10 -> 4 | AK10: =AI10-AJ10 -> 4 | AM10: =AK10-AL10 -> 4 | AO10: =AM10-AN10 -> 4 | AQ10: =AO10-AP10 -> 4 | AS10: =AQ10-AR10 -> 4 | AU10: =AS10-AT10 -> 4 | AW10: =AU10-AV10 -> 4 | AY10: =AW10-AX10 -> 4 | BA10: =AY10-AZ10 -> 4 | BC10: =BA10-BB10 -> 4 | BE10: =BC10-BD10 -> 4 | BG10: =BE10-BF10 -> 4 | BI10: =BG10-BH10 -> 4 | BK10: =BI10-BJ10 -> 4 | BM10: =BK10-BL10 -> 4 | BO10: =BM10-BN10 -> 4 | BQ10: =BO10-BP10 -> 4 | BS10: =BQ10-BR10 -> 4 | BT10: 5
A11: 9 | B11: RTTO5211 | C11: แร็คใหม่ OEM Toyota Hilux Revo 2WD ตัวเตี้ย Innova ปี 15-25 | O11: =SUM(K11:N11) -> 0 | Q11: =มกราคม69!AT11+O11 -> 0 | S11: =Q11-R11 -> 0 | U11: =S11-T11 -> 0 | W11: =U11-V11 -> 0 | Y11: =W11-X11 -> 0 | AA11: =Y11-Z11 -> 0 | AC11: =AA11+AB11 -> 0 | AE11: =AC11-AD11 -> 0 | AG11: =AE11-AF11 -> 0 | AI11: =AG11-AH11 -> 0 | AK11: =AI11-AJ11 -> 0 | AM11: =AK11-AL11 -> 0 | AO11: =AM11-AN11 -> 0 | AQ11: =AO11-AP11 -> 0 | AS11: =AQ11-AR11 -> 0 | AU11: =AS11-AT11 -> 0 | AW11: =AU11-AV11 -> 0 | AY11: =AW11-AX11 -> 0 | BA11: =AY11-AZ11 -> 0 | BC11: =BA11-BB11 -> 0 | BE11: =BC11-BD11 -> 0 | BG11: =BE11-BF11 -> 0 | BI11: =BG11-BH11 -> 0 | BK11: =BI11-BJ11 -> 0 | BM11: =BK11-BL11 -> 0 | BO11: =BM11-BN11 -> 0 | BQ11: =BO11-BP11 -> 0 | BS11: =BQ11-BR11 -> 0 | BT11: 0
A12: 10 | B12: RTTO5210 | C12: แร็คใหม่ OEM Toyota Hilux Revo 4WD ยกสูง Fortuner ปี 15-25 | K12: 6 | O12: =SUM(K12:N12) -> 6 | Q12: =มกราคม69!AT12+O12 -> 6 | S12: =Q12-R12 -> 6 | U12: =S12-T12 -> 6 | W12: =U12-V12 -> 6 | Y12: =W12-X12 -> 6 | Z12: 1 | AA12: =Y12-Z12 -> 5 | AC12: =AA12+AB12 -> 5 | AE12: =AC12-AD12 -> 5 | AG12: =AE12-AF12 -> 5 | AI12: =AG12-AH12 -> 5 | AK12: =AI12-AJ12 -> 5 | AM12: =AK12-AL12 -> 5 | AO12: =AM12-AN12 -> 5 | AQ12: =AO12-AP12 -> 5 | AS12: =AQ12-AR12 -> 5 | AU12: =AS12-AT12 -> 5 | AW12: =AU12-AV12 -> 5 | AY12: =AW12-AX12 -> 5 | BA12: =AY12-AZ12 -> 5 | BC12: =BA12-BB12 -> 5 | BE12: =BC12-BD12 -> 5 | BG12: =BE12-BF12 -> 5 | BI12: =BG12-BH12 -> 5 | BK12: =BI12-BJ12 -> 5 | BM12: =BK12-BL12 -> 5 | BO12: =BM12-BN12 -> 5 | BQ12: =BO12-BP12 -> 5 | BS12: =BQ12-BR12 -> 5 | BT12: 6
A13: 11 | B13: RTTO5213 | C13: แร็คใหม่ OEM Toyota Camry ACV 30 ปี 02-06 | O13: =SUM(K13:N13) -> 0 | Q13: =มกราคม69!AT13+O13 -> 12 | S13: =Q13-R13 -> 12 | U13: =S13-T13 -> 12 | W13: =U13-V13 -> 12 | Y13: =W13-X13 -> 12 | AA13: =Y13-Z13 -> 12 | AC13: =AA13+AB13 -> 12 | AE13: =AC13-AD13 -> 12 | AG13: =AE13-AF13 -> 12 | AI13: =AG13-AH13 -> 12 | AK13: =AI13-AJ13 -> 12 | AM13: =AK13-AL13 -> 12 | AO13: =AM13-AN13 -> 12 | AQ13: =AO13-AP13 -> 12 | AS13: =AQ13-AR13 -> 12 | AU13: =AS13-AT13 -> 12 | AW13: =AU13-AV13 -> 12 | AY13: =AW13-AX13 -> 12 | BA13: =AY13-AZ13 -> 12 | BC13: =BA13-BB13 -> 12 | BE13: =BC13-BD13 -> 12 | BG13: =BE13-BF13 -> 12 | BI13: =BG13-BH13 -> 12 | BK13: =BI13-BJ13 -> 12 | BM13: =BK13-BL13 -> 12 | BO13: =BM13-BN13 -> 12 | BQ13: =BO13-BP13 -> 12 | BS13: =BQ13-BR13 -> 12 | BT13: 6
A14: 12 | B14: RTTO5214 | C14: แร็คใหม่ OEM Toyota Camry ACV 40 ปี 08-2012 เครื่อง 1AZ-2Z | O14: =SUM(K14:N14) -> 0 | Q14: =มกราคม69!AT14+O14 -> 3 | S14: =Q14-R14 -> 3 | U14: =S14-T14 -> 3 | W14: =U14-V14 -> 3 | X14: 1 | Y14: =W14-X14 -> 2 | AA14: =Y14-Z14 -> 2 | AC14: =AA14+AB14 -> 2 | AE14: =AC14-AD14 -> 2 | AG14: =AE14-AF14 -> 2 | AI14: =AG14-AH14 -> 2 | AK14: =AI14-AJ14 -> 2 | AM14: =AK14-AL14 -> 2 | AO14: =AM14-AN14 -> 2 | AQ14: =AO14-AP14 -> 2 | AS14: =AQ14-AR14 -> 2 | AU14: =AS14-AT14 -> 2 | AW14: =AU14-AV14 -> 2 | AY14: =AW14-AX14 -> 2 | BA14: =AY14-AZ14 -> 2 | BC14: =BA14-BB14 -> 2 | BE14: =BC14-BD14 -> 2 | BG14: =BE14-BF14 -> 2 | BI14: =BG14-BH14 -> 2 | BK14: =BI14-BJ14 -> 2 | BM14: =BK14-BL14 -> 2 | BO14: =BM14-BN14 -> 2 | BQ14: =BO14-BP14 -> 2 | BS14: =BQ14-BR14 -> 2 | BT14: 0
A15: 13 | B15: RTTO7209 | C15: แร็คใหม่ OEM Toyota Camry ACV 50 ACV 51 ปี (12-18) | O15: =SUM(K15:N15) -> 0 | Q15: =มกราคม69!AT15+O15 -> 4 | S15: =Q15-R15 -> 4 | U15: =S15-T15 -> 4 | BC15: =BA15-BB15 -> 0 | BE15: =BC15-BD15 -> 0 | BG15: =BE15-BF15 -> 0 | BI15: =BG15-BH15 -> 0 | BK15: =BI15-BJ15 -> 0 | BM15: =BK15-BL15 -> 0 | BO15: =BM15-BN15 -> 0 | BQ15: =BO15-BP15 -> 0 | BS15: =BQ15-BR15 -> 0 | BT15: 0
A16: 14 | B16: RTTO5203 | C16: แร็คใหม่ OEM Toyota Altis, Limo ปี 2001-2007 | O16: =SUM(K16:N16) -> 0 | Q16: =มกราคม69!AT16+O16 -> 11 | S16: =Q16-R16 -> 11 | U16: =S16-T16 -> 11 | BC16: =BA16-BB16 -> 0 | BE16: =BC16-BD16 -> 0 | BG16: =BE16-BF16 -> 0 | BI16: =BG16-BH16 -> 0 | BK16: =BI16-BJ16 -> 0 | BM16: =BK16-BL16 -> 0 | BO16: =BM16-BN16 -> 0 | BQ16: =BO16-BP16 -> 0 | BS16: =BQ16-BR16 -> 0 | BT16: 5
A17: 15 | B17: RTTO7202 | C17: แร็คใหม่ OEM Toyota Altis หน้าแบน เครื่อง 3ZZ 2ZZ ปี 08-12กระบอกไม่มีลายเหลี่ยม | K17: 4 | O17: =SUM(K17:N17) -> 4 | Q17: =มกราคม69!AT17+O17 -> 14 | S17: =Q17-R17 -> 14 | U17: =S17-T17 -> 14 | BC17: =BA17-BB17 -> 0 | BE17: =BC17-BD17 -> 0 | BG17: =BE17-BF17 -> 0 | BI17: =BG17-BH17 -> 0 | BK17: =BI17-BJ17 -> 0 | BM17: =BK17-BL17 -> 0 | BO17: =BM17-BN17 -> 0 | BQ17: =BO17-BP17 -> 0 | BS17: =BQ17-BR17 -> 0 | BT17: 9
A18: 16 | B18: RTTO7203 | C18: แร็คใหม่ OEM Toyota Altis ปี 13-19 | O18: =SUM(K18:N18) -> 0 | Q18: =มกราคม69!AT18+O18 -> 6 | S18: =Q18-R18 -> 6 | U18: =S18-T18 -> 6 | V18: 1 | W18: =U18-V18 -> 5 | Y18: =W18-X18 -> 5 | AA18: =Y18-Z18 -> 5 | AC18: =AA18+AB18 -> 5 | AE18: =AC18-AD18 -> 5 | AG18: =AE18-AF18 -> 5 | AI18: =AG18-AH18 -> 5 | AK18: =AI18-AJ18 -> 5 | AM18: =AK18-AL18 -> 5 | AO18: =AM18-AN18 -> 5 | AQ18: =AO18-AP18 -> 5 | AS18: =AQ18-AR18 -> 5 | AU18: =AS18-AT18 -> 5 | AW18: =AU18-AV18 -> 5 | AY18: =AW18-AX18 -> 5 | BA18: =AY18-AZ18 -> 5 | BC18: =BA18-BB18 -> 5 | BE18: =BC18-BD18 -> 5 | BG18: =BE18-BF18 -> 5 | BI18: =BG18-BH18 -> 5 | BK18: =BI18-BJ18 -> 5 | BM18: =BK18-BL18 -> 5 | BO18: =BM18-BN18 -> 5 | BQ18: =BO18-BP18 -> 5 | BS18: =BQ18-BR18 -> 5 | BT18: 2
A19: 17 | B19: RTTO7208 | C19: แร็คใหม่ OEM Toyota Altis ปี 2019-ป้จจุบัน | O19: =SUM(K19:N19) -> 0 | Q19: =มกราคม69!AT19+O19 -> 2 | S19: =Q19-R19 -> 2 | U19: =S19-T19 -> 2 | BC19: =BA19-BB19 -> 0 | BE19: =BC19-BD19 -> 0 | BG19: =BE19-BF19 -> 0 | BI19: =BG19-BH19 -> 0 | BK19: =BI19-BJ19 -> 0 | BM19: =BK19-BL19 -> 0 | BO19: =BM19-BN19 -> 0 | BQ19: =BO19-BP19 -> 0 | BS19: =BQ19-BR19 -> 0 | BT19: 1
A20: 18 | B20: RTTO5209 | C20: แร็คใหม่ OEM Toyota Vios ปี 02-07 | O20: =SUM(K20:N20) -> 0 | Q20: =มกราคม69!AT20+O20 -> 6 | S20: =Q20-R20 -> 6 | U20: =S20-T20 -> 6 | BC20: =BA20-BB20 -> 0 | BE20: =BC20-BD20 -> 0 | BG20: =BE20-BF20 -> 0 | BI20: =BG20-BH20 -> 0 | BK20: =BI20-BJ20 -> 0 | BM20: =BK20-BL20 -> 0 | BO20: =BM20-BN20 -> 0 | BQ20: =BO20-BP20 -> 0 | BS20: =BQ20-BR20 -> 0 | BT20: 5
A21: 19 | B21: RTTO7201 | C21: แร็คใหม่ OEM Toyota Vios ปี 07-13 /Yaris 1.5 ปี 08-12 | K21: 5 | O21: =SUM(K21:N21) -> 5 | Q21: =มกราคม69!AT21+O21 -> 15 | S21: =Q21-R21 -> 15 | T21: 1 | U21: =S21-T21 -> 14 | W21: =U21-V21 -> 14 | Y21: =W21-X21 -> 14 | AA21: =Y21-Z21 -> 14 | AC21: =AA21+AB21 -> 14 | AE21: =AC21-AD21 -> 14 | AG21: =AE21-AF21 -> 14 | AH21: 2 | AI21: =AG21-AH21 -> 12 | AK21: =AI21-AJ21 -> 12 | AM21: =AK21-AL21 -> 12 | AO21: =AM21-AN21 -> 12 | AQ21: =AO21-AP21 -> 12 | AS21: =AQ21-AR21 -> 12 | AU21: =AS21-AT21 -> 12 | AW21: =AU21-AV21 -> 12 | AY21: =AW21-AX21 -> 12 | BA21: =AY21-AZ21 -> 12 | BC21: =BA21-BB21 -> 12 | BE21: =BC21-BD21 -> 12 | BG21: =BE21-BF21 -> 12 | BI21: =BG21-BH21 -> 12 | BK21: =BI21-BJ21 -> 12 | BM21: =BK21-BL21 -> 12 | BO21: =BM21-BN21 -> 12 | BQ21: =BO21-BP21 -> 12 | BS21: =BQ21-BR21 -> 12 | BT21: 8
A22: 20 | B22: RTTO7204 | C22: แร็คใหม่ OEM Toyota Vios /Yaris 1.2 ปี 13-22 | L22: 6 | O22: =SUM(K22:N22) -> 6 | Q22: =มกราคม69!AT22+O22 -> 11 | S22: =Q22-R22 -> 11 | U22: =S22-T22 -> 11 | W22: =U22-V22 -> 11 | X22: 1 | Y22: =W22-X22 -> 10 | AA22: =Y22-Z22 -> 10 | AC22: =AA22+AB22 -> 10 | AE22: =AC22-AD22 -> 10 | AG22: =AE22-AF22 -> 10 | AI22: =AG22-AH22 -> 10 | AK22: =AI22-AJ22 -> 10 | AM22: =AK22-AL22 -> 10 | AO22: =AM22-AN22 -> 10 | AQ22: =AO22-AP22 -> 10 | AS22: =AQ22-AR22 -> 10 | AU22: =AS22-AT22 -> 10 | AW22: =AU22-AV22 -> 10 | AY22: =AW22-AX22 -> 10 | BA22: =AY22-AZ22 -> 10 | BC22: =BA22-BB22 -> 10 | BE22: =BC22-BD22 -> 10 | BG22: =BE22-BF22 -> 10 | BI22: =BG22-BH22 -> 10 | BK22: =BI22-BJ22 -> 10 | BM22: =BK22-BL22 -> 10 | BO22: =BM22-BN22 -> 10 | BQ22: =BO22-BP22 -> 10 | BS22: =BQ22-BR22 -> 10 | BT22: 7
A23: 21 | B23: RTTO7205 | C23: แร็คใหม่ OEM Toyota Prius (2009-2016) | O23: =SUM(K23:N23) -> 0 | Q23: =มกราคม69!AT23+O23 -> 0 | S23: =Q23-R23 -> 0 | U23: =S23-T23 -> 0 | BC23: =BA23-BB23 -> 0 | BE23: =BC23-BD23 -> 0 | BG23: =BE23-BF23 -> 0 | BI23: =BG23-BH23 -> 0 | BK23: =BI23-BJ23 -> 0 | BM23: =BK23-BL23 -> 0 | BO23: =BM23-BN23 -> 0 | BQ23: =BO23-BP23 -> 0 | BS23: =BQ23-BR23 -> 0
A24: 22 | B24: RTT05205 | C24: แร็คใหม่ OEM Toyota Commuter KDH220 หลังคาสูง ปี 05-18 | O24: =SUM(K24:N24) -> 0 | Q24: =มกราคม69!AT24+O24 -> 6 | S24: =Q24-R24 -> 6 | U24: =S24-T24 -> 6 | W24: =U24-V24 -> 6 | Y24: =W24-X24 -> 6 | AA24: =Y24-Z24 -> 6 | AC24: =AA24+AB24 -> 6 | AE24: =AC24-AD24 -> 6 | AG24: =AE24-AF24 -> 6 | AI24: =AG24-AH24 -> 6 | AK24: =AI24-AJ24 -> 6 | AM24: =AK24-AL24 -> 6 | AO24: =AM24-AN24 -> 6 | AQ24: =AO24-AP24 -> 6 | AS24: =AQ24-AR24 -> 6 | AU24: =AS24-AT24 -> 6 | AW24: =AU24-AV24 -> 6 | AY24: =AW24-AX24 -> 6 | BA24: =AY24-AZ24 -> 6 | BC24: =BA24-BB24 -> 6 | BE24: =BC24-BD24 -> 6 | BG24: =BE24-BF24 -> 6 | BI24: =BG24-BH24 -> 6 | BK24: =BI24-BJ24 -> 6 | BM24: =BK24-BL24 -> 6 | BO24: =BM24-BN24 -> 6 | BQ24: =BO24-BP24 -> 6 | BS24: =BQ24-BR24 -> 6 | BT24: 0
A25: 23 | B25: RTTO5233 | C25: แร็คใหม่ OEM Toyota Hiace Commuter Granvia Majesty ปี 2019-2025 | N25: 2 | O25: =SUM(K25:N25) -> 2 | Q25: =มกราคม69!AT25+O25 -> 3 | S25: =Q25-R25 -> 3 | U25: =S25-T25 -> 3 | W25: =U25-V25 -> 3 | Y25: =W25-X25 -> 3 | AA25: =Y25-Z25 -> 3 | AC25: =AA25+AB25 -> 3 | AE25: =AC25-AD25 -> 3 | AG25: =AE25-AF25 -> 3 | AI25: =AG25-AH25 -> 3 | AK25: =AI25-AJ25 -> 3 | AM25: =AK25-AL25 -> 3 | AO25: =AM25-AN25 -> 3 | AQ25: =AO25-AP25 -> 3 | AS25: =AQ25-AR25 -> 3 | AU25: =AS25-AT25 -> 3 | AW25: =AU25-AV25 -> 3 | AY25: =AW25-AX25 -> 3 | BA25: =AY25-AZ25 -> 3 | BC25: =BA25-BB25 -> 3 | BE25: =BC25-BD25 -> 3 | BG25: =BE25-BF25 -> 3 | BI25: =BG25-BH25 -> 3 | BK25: =BI25-BJ25 -> 3 | BM25: =BK25-BL25 -> 3 | BO25: =BM25-BN25 -> 3 | BQ25: =BO25-BP25 -> 3 | BS25: =BQ25-BR25 -> 3 | BT25: 1
A26: 24 | B26: RTTO5204 | C26: แร็คใหม่ OEM Toyota Hiace LH125/LH112 ปี 1992-2004 ตู้หัวจรด | O26: =SUM(K26:N26) -> 0 | Q26: =มกราคม69!AT26+O26 -> 2 | S26: =Q26-R26 -> 2 | U26: =S26-T26 -> 2 | BC26: =BA26-BB26 -> 0 | BE26: =BC26-BD26 -> 0 | BG26: =BE26-BF26 -> 0 | BI26: =BG26-BH26 -> 0 | BK26: =BI26-BJ26 -> 0 | BM26: =BK26-BL26 -> 0 | BO26: =BM26-BN26 -> 0 | BQ26: =BO26-BP26 -> 0 | BS26: =BQ26-BR26 -> 0 | BT26: 1
A27: 25 | B27: RTTO5211 | C27: แร็คใหม่ OEM Toyota Revo 2WD/ Innova ปี 15-ปัจจุบัน | O27: =SUM(K27:N27) -> 0 | Q27: =มกราคม69!AT27+O27 -> 2 | S27: =Q27-R27 -> 2 | U27: =S27-T27 -> 2 | BC27: =BA27-BB27 -> 0 | BE27: =BC27-BD27 -> 0 | BG27: =BE27-BF27 -> 0 | BI27: =BG27-BH27 -> 0 | BK27: =BI27-BJ27 -> 0 | BM27: =BK27-BL27 -> 0 | BO27: =BM27-BN27 -> 0 | BQ27: =BO27-BP27 -> 0 | BS27: =BQ27-BR27 -> 0 | BT27: 0
A28: 26 | B28: RTTO5210 | C28: แร็คใหม่ OEM Toyota Revo 4WD/ Fortuner ปี 15-ปัจจุบัน | O28: =SUM(K28:N28) -> 0 | Q28: =มกราคม69!AT28+O28 -> 1 | S28: =Q28-R28 -> 1 | U28: =S28-T28 -> 1 | BC28: =BA28-BB28 -> 0 | BE28: =BC28-BD28 -> 0 | BG28: =BE28-BF28 -> 0 | BI28: =BG28-BH28 -> 0 | BK28: =BI28-BJ28 -> 0 | BM28: =BK28-BL28 -> 0 | BO28: =BM28-BN28 -> 0 | BQ28: =BO28-BP28 -> 0 | BS28: =BQ28-BR28 -> 0 | BT28: 6
A29: 27 | B29: RTTO7225 | C29: แร็คใหม่ OEM Toyota RX270/350/450H/AGL10/GGL1 ปี 08-15 | O29: =SUM(K29:N29) -> 0 | Q29: =มกราคม69!AT29+O29 -> 4 | S29: =Q29-R29 -> 4 | U29: =S29-T29 -> 4 | W29: =U29-V29 -> 4 | Y29: =W29-X29 -> 4 | AA29: =Y29-Z29 -> 4 | AC29: =AA29+AB29 -> 4 | AE29: =AC29-AD29 -> 4 | AG29: =AE29-AF29 -> 4 | AI29: =AG29-AH29 -> 4 | AK29: =AI29-AJ29 -> 4 | AM29: =AK29-AL29 -> 4 | AO29: =AM29-AN29 -> 4 | AQ29: =AO29-AP29 -> 4 | AS29: =AQ29-AR29 -> 4 | AU29: =AS29-AT29 -> 4 | AW29: =AU29-AV29 -> 4 | AY29: =AW29-AX29 -> 4 | BA29: =AY29-AZ29 -> 4 | BC29: =BA29-BB29 -> 4 | BE29: =BC29-BD29 -> 4 | BG29: =BE29-BF29 -> 4 | BI29: =BG29-BH29 -> 4 | BK29: =BI29-BJ29 -> 4 | BM29: =BK29-BL29 -> 4 | BO29: =BM29-BN29 -> 4 | BQ29: =BO29-BP29 -> 4 | BS29: =BQ29-BR29 -> 4 | BT29: 0
A30: 28 | B30: RTTO5206 | C30: แร็คใหม่ OEM Toyota Vigo 2WD Innova ปี 2004-2015 | K30: 2 | O30: =SUM(K30:N30) -> 2 | Q30: =มกราคม69!AT30+O30 -> 7 | R30: 1 | S30: =Q30-R30 -> 6 | U30: =S30-T30 -> 6 | BC30: =BA30-BB30 -> 0 | BE30: =BC30-BD30 -> 0 | BG30: =BE30-BF30 -> 0 | BI30: =BG30-BH30 -> 0 | BK30: =BI30-BJ30 -> 0 | BM30: =BK30-BL30 -> 0 | BO30: =BM30-BN30 -> 0 | BQ30: =BO30-BP30 -> 0 | BS30: =BQ30-BR30 -> 0 | BT30: 8
A31: 29 | B31: RTTO5207 | C31: แร็คใหม่ OEM Toyota Vigo 4WD ยกสูง Fortuner ปี 04-14 | K31: 2 | O31: =SUM(K31:N31) -> 2 | Q31: =มกราคม69!AT31+O31 -> 12 | S31: =Q31-R31 -> 12 | U31: =S31-T31 -> 12 | AB31: 1 | BC31: =BA31-BB31 -> 0 | BE31: =BC31-BD31 -> 0 | BG31: =BE31-BF31 -> 0 | BI31: =BG31-BH31 -> 0 | BK31: =BI31-BJ31 -> 0 | BM31: =BK31-BL31 -> 0 | BO31: =BM31-BN31 -> 0 | BQ31: =BO31-BP31 -> 0 | BS31: =BQ31-BR31 -> 0 | BT31: 5
A32: 30 | B32: RTHO5202 | C32: แร็คใหม่ OEM Honda Accord G-7 ปี 2003-2007 ปลาวาฬ | O32: =SUM(K32:N32) -> 0 | Q32: =มกราคม69!AT33+O32 -> 4 | S32: =Q32-R32 -> 4 | U32: =S32-T32 -> 4 | BC32: =BA32-BB32 -> 0 | BE32: =BC32-BD32 -> 0 | BG32: =BE32-BF32 -> 0 | BI32: =BG32-BH32 -> 0 | BK32: =BI32-BJ32 -> 0 | BM32: =BK32-BL32 -> 0 | BO32: =BM32-BN32 -> 0 | BQ32: =BO32-BP32 -> 0 | BS32: =BQ32-BR32 -> 0 | BT32: 2
A33: 31 | B33: RTHO5211 | C33: แร็คใหม่ OEM Honda Accord G-8 ปี 2008-2012 | O33: =SUM(K33:N33) -> 0 | Q33: =มกราคม69!AT34+O33 -> 8 | S33: =Q33-R33 -> 8 | U33: =S33-T33 -> 8 | BC33: =BA33-BB33 -> 0 | BE33: =BC33-BD33 -> 0 | BG33: =BE33-BF33 -> 0 | BI33: =BG33-BH33 -> 0 | BK33: =BI33-BJ33 -> 0 | BM33: =BK33-BL33 -> 0 | BO33: =BM33-BN33 -> 0 | BQ33: =BO33-BP33 -> 0 | BS33: =BQ33-BR33 -> 0 | BT33: 4
A34: 32 | B34: RTHO5207 | C34: แร็คใหม่ OEM Honda CR-V G1 ปี 1996-2001 | O34: =SUM(K34:N34) -> 0 | Q34: =มกราคม69!AT35+O34 -> 4 | S34: =Q34-R34 -> 4 | U34: =S34-T34 -> 4 | BC34: =BA34-BB34 -> 0 | BE34: =BC34-BD34 -> 0 | BG34: =BE34-BF34 -> 0 | BI34: =BG34-BH34 -> 0 | BK34: =BI34-BJ34 -> 0 | BM34: =BK34-BL34 -> 0 | BO34: =BM34-BN34 -> 0 | BQ34: =BO34-BP34 -> 0 | BS34: =BQ34-BR34 -> 0 | BT34: 2
A35: 33 | B35: RTHO5205 | C35: แร็คใหม่ OEM Honda CR-V G2 ปี 2002-2006 | O35: =SUM(K35:N35) -> 0 | Q35: =มกราคม69!AT36+O35 -> 4 | S35: =Q35-R35 -> 4 | U35: =S35-T35 -> 4 | BC35: =BA35-BB35 -> 0 | BE35: =BC35-BD35 -> 0 | BG35: =BE35-BF35 -> 0 | BI35: =BG35-BH35 -> 0 | BK35: =BI35-BJ35 -> 0 | BM35: =BK35-BL35 -> 0 | BO35: =BM35-BN35 -> 0 | BQ35: =BO35-BP35 -> 0 | BS35: =BQ35-BR35 -> 0 | BT35: 2
A36: 34 | B36: RTHO5204 | C36: แร็คใหม่ OEM Honda Civic FD (น้้ามัน) ปี 06-11 | O36: =SUM(K36:N36) -> 0 | Q36: =มกราคม69!AT37+O36 -> 12 | S36: =Q36-R36 -> 12 | U36: =S36-T36 -> 12 | AD36: 1 | AF36: 1 | BC36: =BA36-BB36 -> 0 | BE36: =BC36-BD36 -> 0 | BG36: =BE36-BF36 -> 0 | BI36: =BG36-BH36 -> 0 | BK36: =BI36-BJ36 -> 0 | BM36: =BK36-BL36 -> 0 | BO36: =BM36-BN36 -> 0 | BQ36: =BO36-BP36 -> 0 | BS36: =BQ36-BR36 -> 0 | BT36: 4
A37: 35 | B37: RTHO5206 | C37: แร็คใหม่ OEM Honda Civic Dimension ES ปี 2001-2005 | O37: =SUM(K37:N37) -> 0 | Q37: =มกราคม69!AT38+O37 -> 4 | S37: =Q37-R37 -> 4 | U37: =S37-T37 -> 4 | W37: =U37-V37 -> 4 | Y37: =W37-X37 -> 4 | AA37: =Y37-Z37 -> 4 | AC37: =AA37-AB37 -> 4 | AE37: =AC37-AD37 -> 4 | AG37: =AE37-AF37 -> 4 | AI37: =AG37-AH37 -> 4 | AK37: =AI37-AJ37 -> 4 | AM37: =AK37-AL37 -> 4 | AO37: =AM37-AN37 -> 4 | AQ37: =AO37-AP37 -> 4 | AS37: =AQ37-AR37 -> 4 | AU37: =AS37-AT37 -> 4 | AW37: =AU37-AV37 -> 4 | AY37: =AW37-AX37 -> 4 | BA37: =AY37-AZ37 -> 4 | BC37: =BA37-BB37 -> 4 | BE37: =BC37-BD37 -> 4 | BG37: =BE37-BF37 -> 4 | BI37: =BG37-BH37 -> 4 | BK37: =BI37-BJ37 -> 4 | BM37: =BK37-BL37 -> 4 | BO37: =BM37-BN37 -> 4 | BQ37: =BO37-BP37 -> 4 | BS37: =BQ37-BR37 -> 4 | BT37: 2
A38: 36 | B38: RTHO7203 | C38: แร็คใหม่ OEM Honda HR-V 2WD ปี 2015-2021 | K38: 8 | O38: =SUM(K38:N38) -> 8 | Q38: =มกราคม69!AT39+O38 -> 9 | S38: =Q38-R38 -> 9 | T38: 1 | AB38: 1 | BC38: =BA38-BB38 -> 0 | BE38: =BC38-BD38 -> 0 | BG38: =BE38-BF38 -> 0 | BI38: =BG38-BH38 -> 0 | BK38: =BI38-BJ38 -> 0 | BM38: =BK38-BL38 -> 0 | BO38: =BM38-BN38 -> 0 | BQ38: =BO38-BP38 -> 0 | BS38: =BQ38-BR38 -> 0 | BT38: 7
A39: 37 | B39: RTHO5203 | C39: แร็คใหม่ OEM Honda City Type Z ปี 1995-2002 | O39: =SUM(K39:N39) -> 0 | Q39: =มกราคม69!AT40+O39 -> 4 | S39: =Q39-R39 -> 4 | U39: =S39-T39 -> 4 | W39: =U39-V39 -> 4 | Y39: =W39-X39 -> 4 | AA39: =Y39-Z39 -> 4 | AC39: =AA39+AB39 -> 4 | AE39: =AC39-AD39 -> 4 | AG39: =AE39-AF39 -> 4 | AI39: =AG39-AH39 -> 4 | AK39: =AI39-AJ39 -> 4 | AM39: =AK39-AL39 -> 4 | AO39: =AM39-AN39 -> 4 | AQ39: =AO39-AP39 -> 4 | AS39: =AQ39-AR39 -> 4 | AU39: =AS39-AT39 -> 4 | AW39: =AU39-AV39 -> 4 | AY39: =AW39-AX39 -> 4 | BA39: =AY39-AZ39 -> 4 | BC39: =BA39-BB39 -> 4 | BE39: =BC39-BD39 -> 4 | BG39: =BE39-BF39 -> 4 | BI39: =BG39-BH39 -> 4 | BK39: =BI39-BJ39 -> 4 | BM39: =BK39-BL39 -> 4 | BO39: =BM39-BN39 -> 4 | BQ39: =BO39-BP39 -> 4 | BS39: =BQ39-BR39 -> 4 | BT39: 2
A40: 38 | B40: RTHO7202 | C40: แร็คใหม่ OEM Honda City/Jazz GM6 GK ปี 14-19 | K40: 8 | O40: =SUM(K40:N40) -> 8 | Q40: =มกราคม69!AT41+O40 -> 8 | S40: =Q40-R40 -> 8 | U40: =S40-T40 -> 8 | W40: =U40-V40 -> 8 | Y40: =W40-X40 -> 8 | AA40: =Y40-Z40 -> 8 | AC40: =AA40+AB40 -> 8 | AE40: =AC40-AD40 -> 8 | AG40: =AE40-AF40 -> 8 | AI40: =AG40-AH40 -> 8 | AK40: =AI40-AJ40 -> 8 | AM40: =AK40-AL40 -> 8 | AO40: =AM40-AN40 -> 8 | AQ40: =AO40-AP40 -> 8 | AS40: =AQ40-AR40 -> 8 | AU40: =AS40-AT40 -> 8 | AW40: =AU40-AV40 -> 8 | AY40: =AW40-AX40 -> 8 | BA40: =AY40-AZ40 -> 8 | BC40: =BA40-BB40 -> 8 | BE40: =BC40-BD40 -> 8 | BG40: =BE40-BF40 -> 8 | BI40: =BG40-BH40 -> 8 | BK40: =BI40-BJ40 -> 8 | BM40: =BK40-BL40 -> 8 | BO40: =BM40-BN40 -> 8 | BQ40: =BO40-BP40 -> 8 | BS40: =BQ40-BR40 -> 8 | BT40: 8
...

Sheet มค.69(new)
A1: แร็คพวงมาลัย | I1: มกราคม.2569
A2: No. | B2: Parts | C2: รายการแร็ค OEM | H2: 23.01 | I2: 27.01 | L2: รวมเข้า | M2: 13.01 | N2: เหลือ | O2: 14.01 | P2: เหลือ | Q2: 15.01 | R2: เหลือ | S2: 16.01 | T2: เหลือ | U2: 18.01 | V2: เหลือ | W2: 19.01 | X2: เหลือ | Y2: 20.01 | Z2: เหลือ | AA2: 21.01 | AB2: เหลือ | AC2: 22.01 | AD2: เหลือ | AE2: 23.01 | AF2: เหลือ | AG2: 24.01 | AH2: เหลือ | AI2: 25.01 | AJ2: เหลือ | AK2: 26.01 | AL2: เหลือ | AM2: 27.01 | AN2: เหลือ | AO2: 28.01 | AP2: เหลือ | AQ2: 30.01 | AR2: เหลือ | AS2: 31.01 | AT2: เหลือ
A3: 1 | B3: RTTO5201 | C3: แร็ค TOYOTA COROLLA AE100 AE111 AE112 ปี 1991-2000 | H3: 2 | L3: =SUM(H3:K3) -> 2 | N3: =L3 -> 2 | P3: =N3-O3 -> 2 | R3: =P3-Q3 -> 2 | T3: =R3-S3 -> 2 | V3: =T3+U3 -> 2 | X3: =V3-W3 -> 2 | Z3: =X3-Y3 -> 2 | AB3: =Z3-AA3 -> 2 | AD3: =AB3-AC3 -> 2 | AF3: =AD3-AE3 -> 2 | AH3: =AF3-AG3 -> 2 | AJ3: =AH3-AI3 -> 2 | AL3: =AJ3-AK3 -> 2 | AN3: =AL3-AM3 -> 2 | AP3: =AN3-AO3 -> 2 | AR3: =AP3-AQ3 -> 2 | AT3: =AR3-AS3 -> 2 | AU3: 2
A4: 2 | B4: RTTO5203 | C4: แร็ค TOYOTA COROLLA ALTIS LIMO ZZE121 ปี 2001-2007 | H4: 6 | L4: =SUM(H4:K4) -> 6 | N4: =L4 -> 6 | P4: =N4-O4 -> 6 | R4: =P4-Q4 -> 6 | T4: =R4-S4 -> 6 | V4: =T4+U4 -> 6 | X4: =V4-W4 -> 6 | Z4: =X4-Y4 -> 6 | AB4: =Z4-AA4 -> 6 | AD4: =AB4-AC4 -> 6 | AF4: =AD4-AE4 -> 6 | AH4: =AF4-AG4 -> 6 | AJ4: =AH4-AI4 -> 6 | AL4: =AJ4-AK4 -> 6 | AN4: =AL4-AM4 -> 6 | AP4: =AN4-AO4 -> 6 | AR4: =AP4-AQ4 -> 6 | AT4: =AR4-AS4 -> 6 | AU4: 6
A5: 3 | B5: RTTO5203-1 | C5: แร็ค TOYOTA COROLLA ALTIS น้ำมัน | L5: =SUM(H5:K5) -> 0 | N5: =L5 -> 0 | P5: =N5-O5 -> 0 | R5: =P5-Q5 -> 0 | T5: =R5-S5 -> 0 | V5: =T5+U5 -> 0 | X5: =V5-W5 -> 0 | Z5: =X5-Y5 -> 0 | AB5: =Z5-AA5 -> 0 | AD5: =AB5-AC5 -> 0 | AF5: =AD5-AE5 -> 0 | AH5: =AF5-AG5 -> 0 | AJ5: =AH5-AI5 -> 0 | AL5: =AJ5-AK5 -> 0 | AN5: =AL5-AM5 -> 0 | AP5: =AN5-AO5 -> 0 | AR5: =AP5-AQ5 -> 0 | AT5: =AR5-AS5 -> 0 | AU5: 0
A6: 4 | B6: RTTO7202 | C6: แร็ค TOYOTA COROLLA ALTIS DUO ดูโอ้ ปี 2008 | H6: 6 | L6: =SUM(H6:K6) -> 6 | N6: =L6 -> 6 | P6: =N6-O6 -> 6 | R6: =P6-Q6 -> 6 | T6: =R6-S6 -> 6 | V6: =T6+U6 -> 6 | X6: =V6-W6 -> 6 | Z6: =X6-Y6 -> 6 | AB6: =Z6-AA6 -> 6 | AD6: =AB6-AC6 -> 6 | AF6: =AD6-AE6 -> 6 | AH6: =AF6-AG6 -> 6 | AI6: 1 | AJ6: =AH6-AI6 -> 5 | AL6: =AJ6-AK6 -> 5 | AN6: =AL6-AM6 -> 5 | AP6: =AN6-AO6 -> 5 | AR6: =AP6-AQ6 -> 5 | AT6: =AR6-AS6 -> 5 | AU6: 5
A7: 5 | B7: RTTO7203 | C7: แร็ค TOYOTA COROLLA ALTIS ZRE171 ปี 2014-2018 | H7: 4 | L7: =SUM(H7:K7) -> 4 | N7: =L7 -> 4 | P7: =N7-O7 -> 4 | R7: =P7-Q7 -> 4 | T7: =R7-S7 -> 4 | V7: =T7+U7 -> 4 | X7: =V7-W7 -> 4 | Z7: =X7-Y7 -> 4 | AB7: =Z7-AA7 -> 4 | AD7: =AB7-AC7 -> 4 | AF7: =AD7-AE7 -> 4 | AG7: 1 | AH7: =AF7-AG7 -> 3 | AJ7: =AH7-AI7 -> 3 | AL7: =AJ7-AK7 -> 3 | AN7: =AL7-AM7 -> 3 | AP7: =AN7-AO7 -> 3 | AR7: =AP7-AQ7 -> 3 | AT7: =AR7-AS7 -> 3 | AU7: 3
A8: 6 | B8: RTTO7208 | C8: แร็ค TOYOTA COROLLA ALTIS ZRE21# ปี 2019-2025 | H8: 1 | L8: =SUM(H8:K8) -> 1 | N8: =L8 -> 1 | P8: =N8-O8 -> 1 | R8: =P8-Q8 -> 1 | T8: =R8-S8 -> 1 | V8: =T8+U8 -> 1 | X8: =V8-W8 -> 1 | Z8: =X8-Y8 -> 1 | AB8: =Z8-AA8 -> 1 | AD8: =AB8-AC8 -> 1 | AF8: =AD8-AE8 -> 1 | AH8: =AF8-AG8 -> 1 | AJ8: =AH8-AI8 -> 1 | AL8: =AJ8-AK8 -> 1 | AN8: =AL8-AM8 -> 1 | AP8: =AN8-AO8 -> 1 | AR8: =AP8-AQ8 -> 1 | AT8: =AR8-AS8 -> 1 | AU8: 1
A9: 7 | B9: RTTO5204 | C9: แร็ค TOYOTA HIACE YH71 LH112 LH125 รถตู้ ไฮเอช ปี 1987-2004 ตู้หัวจรวด | H9: 1 | L9: =SUM(H9:K9) -> 1 | N9: =L9 -> 1 | P9: =N9-O9 -> 1 | R9: =P9-Q9 -> 1 | T9: =R9-S9 -> 1 | V9: =T9+U9 -> 1 | X9: =V9-W9 -> 1 | Z9: =X9-Y9 -> 1 | AB9: =Z9-AA9 -> 1 | AD9: =AB9-AC9 -> 1 | AF9: =AD9-AE9 -> 1 | AH9: =AF9-AG9 -> 1 | AJ9: =AH9-AI9 -> 1 | AL9: =AJ9-AK9 -> 1 | AN9: =AL9-AM9 -> 1 | AP9: =AN9-AO9 -> 1 | AR9: =AP9-AQ9 -> 1 | AT9: =AR9-AS9 -> 1 | AU9: 1
A10: 8 | B10: RTTO5232 | C10: แร็ค TOYOTA HIACE SUPER CUSTOM 4WD รถตู้หัวจรวด 3L 5L ปี 1987-2004 | L10: =SUM(H10:K10) -> 0 | N10: =L10 -> 0 | P10: =N10-O10 -> 0 | R10: =P10-Q10 -> 0 | T10: =R10-S10 -> 0 | V10: =T10+U10 -> 0 | X10: =V10-W10 -> 0 | Z10: =X10-Y10 -> 0 | AB10: =Z10-AA10 -> 0 | AD10: =AB10-AC10 -> 0 | AF10: =AD10-AE10 -> 0 | AH10: =AF10-AG10 -> 0 | AJ10: =AH10-AI10 -> 0 | AL10: =AJ10-AK10 -> 0 | AN10: =AL10-AM10 -> 0 | AP10: =AN10-AO10 -> 0 | AR10: =AP10-AQ10 -> 0 | AT10: =AR10-AS10 -> 0 | AU10: 0
A11: 9 | B11: RTTO5205 | C11: แร็ค TOYOTA HIACE COMMUTER KDH220 หลังคาสูง ปี 2005-2018 | H11: 6 | L11: =SUM(H11:K11) -> 6 | N11: =L11 -> 6 | P11: =N11-O11 -> 6 | R11: =P11-Q11 -> 6 | T11: =R11-S11 -> 6 | V11: =T11+U11 -> 6 | X11: =V11-W11 -> 6 | Z11: =X11-Y11 -> 6 | AB11: =Z11-AA11 -> 6 | AD11: =AB11-AC11 -> 6 | AF11: =AD11-AE11 -> 6 | AH11: =AF11-AG11 -> 6 | AJ11: =AH11-AI11 -> 6 | AL11: =AJ11-AK11 -> 6 | AN11: =AL11-AM11 -> 6 | AP11: =AN11-AO11 -> 6 | AR11: =AP11-AQ11 -> 6 | AT11: =AR11-AS11 -> 6 | AU11: 6
A12: 10 | B12: RTTO5205-1 | C12: แร็ค TOYOTA HIACE COMMUTER KDH200 หลังคาเตี้ย ปี 2005-2018 | H12: 1 | L12: =SUM(H12:K12) -> 1 | N12: =L12 -> 1 | P12: =N12-O12 -> 1 | R12: =P12-Q12 -> 1 | T12: =R12-S12 -> 1 | V12: =T12+U12 -> 1 | X12: =V12-W12 -> 1 | Z12: =X12-Y12 -> 1 | AB12: =Z12-AA12 -> 1 | AD12: =AB12-AC12 -> 1 | AF12: =AD12-AE12 -> 1 | AH12: =AF12-AG12 -> 1 | AJ12: =AH12-AI12 -> 1 | AL12: =AJ12-AK12 -> 1 | AN12: =AL12-AM12 -> 1 | AP12: =AN12-AO12 -> 1 | AR12: =AP12-AQ12 -> 1 | AT12: =AR12-AS12 -> 1 | AU12: 1
A13: 11 | B13: RTTO5233 | C13: แร็ค TOYOTA HIACE COMMUTER GRANVIA MAJESTY ปี 2019-2025 | L13: =SUM(H13:K13) -> 0 | N13: =L13 -> 0 | P13: =N13-O13 -> 0 | R13: =P13-Q13 -> 0 | T13: =R13-S13 -> 0 | V13: =T13+U13 -> 0 | X13: =V13-W13 -> 0 | Z13: =X13-Y13 -> 0 | AB13: =Z13-AA13 -> 0 | AD13: =AB13-AC13 -> 0 | AF13: =AD13-AE13 -> 0 | AH13: =AF13-AG13 -> 0 | AJ13: =AH13-AI13 -> 0 | AL13: =AJ13-AK13 -> 0 | AN13: =AL13-AM13 -> 0 | AP13: =AN13-AO13 -> 0 | AR13: =AP13-AQ13 -> 0 | AT13: =AR13-AS13 -> 0 | AU13: 0
A14: 12 | B14: RTTO7240 | C14: แร็ค TOYOTA HILUX VIGO 2WD ปี 2004-2015 ธรรมดา ไม่พาวเวอร์ | L14: =SUM(H14:K14) -> 0 | N14: =L14 -> 0 | P14: =N14-O14 -> 0 | R14: =P14-Q14 -> 0 | T14: =R14-S14 -> 0 | V14: =T14+U14 -> 0 | X14: =V14-W14 -> 0 | Z14: =X14-Y14 -> 0 | AB14: =Z14-AA14 -> 0 | AD14: =AB14-AC14 -> 0 | AF14: =AD14-AE14 -> 0 | AH14: =AF14-AG14 -> 0 | AJ14: =AH14-AI14 -> 0 | AL14: =AJ14-AK14 -> 0 | AN14: =AL14-AM14 -> 0 | AP14: =AN14-AO14 -> 0 | AR14: =AP14-AQ14 -> 0 | AT14: =AR14-AS14 -> 0 | AU14: 0
A15: 13 | B15: RTTO5206 | C15: แร็ค TOYOTA VIGO 2WD ตัวเตี้ย INNOVA ปี 2004-2015 | H15: 5 | L15: =SUM(H15:K15) -> 5 | N15: =L15 -> 5 | P15: =N15-O15 -> 5 | R15: =P15-Q15 -> 5 | T15: =R15-S15 -> 5 | V15: =T15+U15 -> 5 | X15: =V15-W15 -> 5 | Z15: =X15-Y15 -> 5 | AB15: =Z15-AA15 -> 5 | AD15: =AB15-AC15 -> 5 | AF15: =AD15-AE15 -> 5 | AH15: =AF15-AG15 -> 5 | AJ15: =AH15-AI15 -> 5 | AL15: =AJ15-AK15 -> 5 | AN15: =AL15-AM15 -> 5 | AP15: =AN15-AO15 -> 5 | AR15: =AP15-AQ15 -> 5 | AT15: =AR15-AS15 -> 5 | AU15: 5
A16: 14 | B16: RTTO5207 | C16: แร็ค TOYOTA VIGO 4WD ยกสูง FORTUNER ปี 2004-2015 | H16: 5 | L16: =SUM(H16:K16) -> 5 | N16: =L16 -> 5 | P16: =N16-O16 -> 5 | R16: =P16-Q16 -> 5 | T16: =R16-S16 -> 5 | V16: =T16+U16 -> 5 | X16: =V16-W16 -> 5 | Z16: =X16-Y16 -> 5 | AB16: =Z16-AA16 -> 5 | AD16: =AB16-AC16 -> 5 | AF16: =AD16-AE16 -> 5 | AH16: =AF16-AG16 -> 5 | AJ16: =AH16-AI16 -> 5 | AL16: =AJ16-AK16 -> 5 | AN16: =AL16-AM16 -> 5 | AP16: =AN16-AO16 -> 5 | AQ16: 1 | AR16: =AP16-AQ16 -> 4 | AT16: =AR16-AS16 -> 4 | AU16: 4
A17: 15 | B17: RTTO5210 | C17: แร็ค TOYOTA HILUX REVO 4WD ยกสูง FORTUNER ปี 2015-2025 | H17: 1 | L17: =SUM(H17:K17) -> 1 | N17: =L17 -> 1 | P17: =N17-O17 -> 1 | R17: =P17-Q17 -> 1 | T17: =R17-S17 -> 1 | V17: =T17+U17 -> 1 | X17: =V17-W17 -> 1 | Z17: =X17-Y17 -> 1 | AB17: =Z17-AA17 -> 1 | AD17: =AB17-AC17 -> 1 | AF17: =AD17-AE17 -> 1 | AH17: =AF17-AG17 -> 1 | AJ17: =AH17-AI17 -> 1 | AL17: =AJ17-AK17 -> 1 | AN17: =AL17-AM17 -> 1 | AP17: =AN17-AO17 -> 1 | AR17: =AP17-AQ17 -> 1 | AT17: =AR17-AS17 -> 1 | AU17: 1
A18: 16 | B18: RTTO5211 | C18: แร็ค TOYOTA HILUX REVO 2WD ตัวเตี้ย INNOVA ปี 2015-2025 | H18: 2 | L18: =SUM(H18:K18) -> 2 | N18: =L18 -> 2 | P18: =N18-O18 -> 2 | R18: =P18-Q18 -> 2 | T18: =R18-S18 -> 2 | V18: =T18+U18 -> 2 | X18: =V18-W18 -> 2 | Z18: =X18-Y18 -> 2 | AB18: =Z18-AA18 -> 2 | AD18: =AB18-AC18 -> 2 | AF18: =AD18-AE18 -> 2 | AH18: =AF18-AG18 -> 2 | AJ18: =AH18-AI18 -> 2 | AL18: =AJ18-AK18 -> 2 | AN18: =AL18-AM18 -> 2 | AP18: =AN18-AO18 -> 2 | AR18: =AP18-AQ18 -> 2 | AT18: =AR18-AS18 -> 2 | AU18: 2
A19: 17 | B19: RTTO5222 | C19: แร็ค TOYOTA SOLUNA AL50 ปี 1997-2002 ไฟหยดน้า 3 รู | L19: =SUM(H19:K19) -> 0 | N19: =L19 -> 0 | P19: =N19-O19 -> 0 | R19: =P19-Q19 -> 0 | T19: =R19-S19 -> 0 | V19: =T19+U19 -> 0 | X19: =V19-W19 -> 0 | Z19: =X19-Y19 -> 0 | AB19: =Z19-AA19 -> 0 | AD19: =AB19-AC19 -> 0 | AF19: =AD19-AE19 -> 0 | AH19: =AF19-AG19 -> 0 | AJ19: =AH19-AI19 -> 0 | AL19: =AJ19-AK19 -> 0 | AN19: =AL19-AM19 -> 0 | AP19: =AN19-AO19 -> 0 | AR19: =AP19-AQ19 -> 0 | AT19: =AR19-AS19 -> 0 | AU19: 0
A20: 18 | B20: RTTO5209 | C20: แร็ค TOYOTA VIOS วีออส ปี 2002-2007 | H20: 2 | L20: =SUM(H20:K20) -> 2 | N20: =L20 -> 2 | P20: =N20-O20 -> 2 | R20: =P20-Q20 -> 2 | T20: =R20-S20 -> 2 | V20: =T20+U20 -> 2 | X20: =V20-W20 -> 2 | Z20: =X20-Y20 -> 2 | AB20: =Z20-AA20 -> 2 | AD20: =AB20-AC20 -> 2 | AF20: =AD20-AE20 -> 2 | AH20: =AF20-AG20 -> 2 | AJ20: =AH20-AI20 -> 2 | AL20: =AJ20-AK20 -> 2 | AN20: =AL20-AM20 -> 2 | AP20: =AN20-AO20 -> 2 | AQ20: 1 | AR20: =AP20-AQ20 -> 1 | AT20: =AR20-AS20 -> 1 | AU20: 1
A21: 19 | B21: RTTO7201 | C21: แร็ค TOYOTA VIOS วีออส ปี 2008-2012 YARIS ยาริส 1.5 ปี 2006-2013 | H21: 7 | L21: =SUM(H21:K21) -> 7 | N21: =L21 -> 7 | P21: =N21-O21 -> 7 | R21: =P21-Q21 -> 7 | T21: =R21-S21 -> 7 | V21: =T21+U21 -> 7 | X21: =V21-W21 -> 7 | Z21: =X21-Y21 -> 7 | AB21: =Z21-AA21 -> 7 | AD21: =AB21-AC21 -> 7 | AF21: =AD21-AE21 -> 7 | AG21: 1 | AH21: =AF21-AG21 -> 6 | AJ21: =AH21-AI21 -> 6 | AK21: 1 | AL21: =AJ21-AK21 -> 5 | AN21: =AL21-AM21 -> 5 | AP21: =AN21-AO21 -> 5 | AR21: =AP21-AQ21 -> 5 | AS21: 1 | AT21: =AR21-AS21 -> 4 | AU21: 4
A22: 20 | B22: RTTO7204 | C22: แร็ค TOYOTA VIOS นิววีออส YARIS ยาริส 1.2 ปี 2013-2022 | H22: 6 | L22: =SUM(H22:K22) -> 6 | N22: =L22 -> 6 | P22: =N22-O22 -> 6 | R22: =P22-Q22 -> 6 | T22: =R22-S22 -> 6 | V22: =T22+U22 -> 6 | X22: =V22-W22 -> 6 | Z22: =X22-Y22 -> 6 | AB22: =Z22-AA22 -> 6 | AD22: =AB22-AC22 -> 6 | AE22: 1 | AF22: =AD22-AE22 -> 5 | AH22: =AF22-AG22 -> 5 | AJ22: =AH22-AI22 -> 5 | AL22: =AJ22-AK22 -> 5 | AN22: =AL22-AM22 -> 5 | AO22: 2 | AP22: =AN22-AO22 -> 3 | AR22: =AP22-AQ22 -> 3 | AT22: =AR22-AS22 -> 3 | AU22: 3
A23: 21 | B23: RTTO5237 | C23: แร็ค TOYOTA CAMRY SXV10 SXV20 แคมรี่ ปี 1997-2001 | L23: =SUM(H23:K23) -> 0 | N23: =L23 -> 0 | P23: =N23-O23 -> 0 | R23: =P23-Q23 -> 0 | T23: =R23-S23 -> 0 | V23: =T23+U23 -> 0 | X23: =V23-W23 -> 0 | Z23: =X23-Y23 -> 0 | AB23: =Z23-AA23 -> 0 | AD23: =AB23-AC23 -> 0 | AF23: =AD23-AE23 -> 0 | AH23: =AF23-AG23 -> 0 | AJ23: =AH23-AI23 -> 0 | AL23: =AJ23-AK23 -> 0 | AN23: =AL23-AM23 -> 0 | AP23: =AN23-AO23 -> 0 | AR23: =AP23-AQ23 -> 0 | AT23: =AR23-AS23 -> 0 | AU23: 0
A24: 22 | B24: RTTO5213 | C24: แร็ค TOYOTA CAMRY ACV30 ปี 2002-2006 | H24: 6 | L24: =SUM(H24:K24) -> 6 | N24: =L24 -> 6 | P24: =N24-O24 -> 6 | R24: =P24-Q24 -> 6 | T24: =R24-S24 -> 6 | V24: =T24+U24 -> 6 | X24: =V24-W24 -> 6 | Z24: =X24-Y24 -> 6 | AB24: =Z24-AA24 -> 6 | AD24: =AB24-AC24 -> 6 | AF24: =AD24-AE24 -> 6 | AH24: =AF24-AG24 -> 6 | AJ24: =AH24-AI24 -> 6 | AL24: =AJ24-AK24 -> 6 | AN24: =AL24-AM24 -> 6 | AP24: =AN24-AO24 -> 6 | AR24: =AP24-AQ24 -> 6 | AT24: =AR24-AS24 -> 6 | AU24: 6
A25: 23 | B25: RTTO5214 | C25: แร็ค TOYOTA CAMRY ACV40 ปี 2006-2012 ไม่ไฮบริด | H25: 2 | L25: =SUM(H25:K25) -> 2 | N25: =L25 -> 2 | P25: =N25-O25 -> 2 | R25: =P25-Q25 -> 2 | T25: =R25-S25 -> 2 | V25: =T25+U25 -> 2 | X25: =V25-W25 -> 2 | Z25: =X25-Y25 -> 2 | AB25: =Z25-AA25 -> 2 | AD25: =AB25-AC25 -> 2 | AF25: =AD25-AE25 -> 2 | AH25: =AF25-AG25 -> 2 | AJ25: =AH25-AI25 -> 2 | AL25: =AJ25-AK25 -> 2 | AN25: =AL25-AM25 -> 2 | AP25: =AN25-AO25 -> 2 | AR25: =AP25-AQ25 -> 2 | AS25: 1 | AT25: =AR25-AS25 -> 1 | AU25: 1
A26: 24 | B26: RTTO7209 | C26: แร็ค TOYOTA CAMRY ACV50 ASV51 ปี 2012-2018 | H26: 4 | L26: =SUM(H26:K26) -> 4 | N26: =L26 -> 4 | P26: =N26-O26 -> 4 | R26: =P26-Q26 -> 4 | T26: =R26-S26 -> 4 | V26: =T26+U26 -> 4 | X26: =V26-W26 -> 4 | Z26: =X26-Y26 -> 4 | AB26: =Z26-AA26 -> 4 | AD26: =AB26-AC26 -> 4 | AF26: =AD26-AE26 -> 4 | AH26: =AF26-AG26 -> 4 | AJ26: =AH26-AI26 -> 4 | AL26: =AJ26-AK26 -> 4 | AN26: =AL26-AM26 -> 4 | AP26: =AN26-AO26 -> 4 | AR26: =AP26-AQ26 -> 4 | AT26: =AR26-AS26 -> 4 | AU26: 4
A27: 25 | B27: RTTO5216 | C27: แร็ค TOYOTA AVANZA 1.3 รหัส K3VE ปี 2003-2006 | L27: =SUM(H27:K27) -> 0 | N27: =L27 -> 0 | P27: =N27-O27 -> 0 | R27: =P27-Q27 -> 0 | T27: =R27-S27 -> 0 | V27: =T27+U27 -> 0 | X27: =V27-W27 -> 0 | Z27: =X27-Y27 -> 0 | AB27: =Z27-AA27 -> 0 | AD27: =AB27-AC27 -> 0 | AF27: =AD27-AE27 -> 0 | AH27: =AF27-AG27 -> 0 | AJ27: =AH27-AI27 -> 0 | AL27: =AJ27-AK27 -> 0 | AN27: =AL27-AM27 -> 0 | AP27: =AN27-AO27 -> 0 | AR27: =AP27-AQ27 -> 0 | AT27: =AR27-AS27 -> 0 | AU27: 0
A28: 26 | B28: RTTO5215 | C28: แร็ค TOYOTA AVANZA 1.5 รหัส 3SZVE ปี 2006-2011 | L28: =SUM(H28:K28) -> 0 | N28: =L28 -> 0 | P28: =N28-O28 -> 0 | R28: =P28-Q28 -> 0 | T28: =R28-S28 -> 0 | V28: =T28+U28 -> 0 | X28: =V28-W28 -> 0 | Z28: =X28-Y28 -> 0 | AB28: =Z28-AA28 -> 0 | AD28: =AB28-AC28 -> 0 | AF28: =AD28-AE28 -> 0 | AH28: =AF28-AG28 -> 0 | AJ28: =AH28-AI28 -> 0 | AL28: =AJ28-AK28 -> 0 | AN28: =AL28-AM28 -> 0 | AP28: =AN28-AO28 -> 0 | AR28: =AP28-AQ28 -> 0 | AT28: =AR28-AS28 -> 0 | AU28: 0
A29: 27 | B29: RTTO7210 | C29: แร็ค TOYOTA AVANZA 1.5 ปี 2011-2022 | L29: =SUM(H29:K29) -> 0 | N29: =L29 -> 0 | P29: =N29-O29 -> 0 | R29: =P29-Q29 -> 0 | T29: =R29-S29 -> 0 | V29: =T29+U29 -> 0 | X29: =V29-W29 -> 0 | Z29: =X29-Y29 -> 0 | AB29: =Z29-AA29 -> 0 | AD29: =AB29-AC29 -> 0 | AF29: =AD29-AE29 -> 0 | AH29: =AF29-AG29 -> 0 | AJ29: =AH29-AI29 -> 0 | AL29: =AJ29-AK29 -> 0 | AN29: =AL29-AM29 -> 0 | AP29: =AN29-AO29 -> 0 | AR29: =AP29-AQ29 -> 0 | AT29: =AR29-AS29 -> 0 | AU29: 0
A30: 28 | B30: RTTO7226 | C30: แร็ค TOYOTA VELOZ AVANZA ปี 2022-2025 | L30: =SUM(H30:K30) -> 0 | N30: =L30 -> 0 | P30: =N30-O30 -> 0 | R30: =P30-Q30 -> 0 | T30: =R30-S30 -> 0 | V30: =T30+U30 -> 0 | X30: =V30-W30 -> 0 | Z30: =X30-Y30 -> 0 | AB30: =Z30-AA30 -> 0 | AD30: =AB30-AC30 -> 0 | AF30: =AD30-AE30 -> 0 | AH30: =AF30-AG30 -> 0 | AJ30: =AH30-AI30 -> 0 | AL30: =AJ30-AK30 -> 0 | AN30: =AL30-AM30 -> 0 | AP30: =AN30-AO30 -> 0 | AR30: =AP30-AQ30 -> 0 | AT30: =AR30-AS30 -> 0 | AU30: 0
A31: 29 | B31: RTTO5217 | C31: แร็ค TOYOTA ALPHARD ESTIMA ACR30 ACR40 ปี 2000-2007 | L31: =SUM(H31:K31) -> 0 | N31: =L31 -> 0 | P31: =N31-O31 -> 0 | R31: =P31-Q31 -> 0 | T31: =R31-S31 -> 0 | V31: =T31+U31 -> 0 | X31: =V31-W31 -> 0 | Z31: =X31-Y31 -> 0 | AB31: =Z31-AA31 -> 0 | AD31: =AB31-AC31 -> 0 | AF31: =AD31-AE31 -> 0 | AH31: =AF31-AG31 -> 0 | AJ31: =AH31-AI31 -> 0 | AL31: =AJ31-AK31 -> 0 | AN31: =AL31-AM31 -> 0 | AP31: =AN31-AO31 -> 0 | AR31: =AP31-AQ31 -> 0 | AT31: =AR31-AS31 -> 0 | AU31: 0
A32: 30 | B32: RTTO7214 | C32: แร็ค TOYOTA ALPHARD ACR50 ปี 2008-2016 | H32: 2 | L32: =SUM(H32:K32) -> 2 | N32: =L32 -> 2 | P32: =N32-O32 -> 2 | R32: =P32-Q32 -> 2 | T32: =R32-S32 -> 2 | V32: =T32+U32 -> 2 | X32: =V32-W32 -> 2 | Z32: =X32-Y32 -> 2 | AB32: =Z32-AA32 -> 2 | AD32: =AB32-AC32 -> 2 | AE32: 1 | AF32: =AD32-AE32 -> 1 | AH32: =AF32-AG32 -> 1 | AJ32: =AH32-AI32 -> 1 | AL32: =AJ32-AK32 -> 1 | AN32: =AL32-AM32 -> 1 | AP32: =AN32-AO32 -> 1 | AR32: =AP32-AQ32 -> 1 | AT32: =AR32-AS32 -> 1 | AU32: 1
A33: 31 | B33: RTTO7216 | C33: แร็ค TOYOTA ALPHARD ACR50 ปี 2008-2016 | L33: =SUM(H33:K33) -> 0 | N33: =L33 -> 0 | P33: =N33-O33 -> 0 | R33: =P33-Q33 -> 0 | T33: =R33-S33 -> 0 | V33: =T33+U33 -> 0 | X33: =V33-W33 -> 0 | Z33: =X33-Y33 -> 0 | AB33: =Z33-AA33 -> 0 | AD33: =AB33-AC33 -> 0 | AF33: =AD33-AE33 -> 0 | AH33: =AF33-AG33 -> 0 | AJ33: =AH33-AI33 -> 0 | AL33: =AJ33-AK33 -> 0 | AN33: =AL33-AM33 -> 0 | AP33: =AN33-AO33 -> 0 | AR33: =AP33-AQ33 -> 0 | AT33: =AR33-AS33 -> 0 | AU33: 0
A34: 32 | B34: RTTO7213 | C34: แร็ค TOYOTA ALPHARD AGH30 ปี 2015-2023 | H34: 3 | L34: =SUM(H34:K34) -> 3 | N34: =L34 -> 3 | P34: =N34-O34 -> 3 | R34: =P34-Q34 -> 3 | T34: =R34-S34 -> 3 | V34: =T34+U34 -> 3 | X34: =V34-W34 -> 3 | Z34: =X34-Y34 -> 3 | AB34: =Z34-AA34 -> 3 | AD34: =AB34-AC34 -> 3 | AF34: =AD34-AE34 -> 3 | AG34: 1 | AH34: =AF34-AG34 -> 2 | AJ34: =AH34-AI34 -> 2 | AL34: =AJ34-AK34 -> 2 | AN34: =AL34-AM34 -> 2 | AP34: =AN34-AO34 -> 2 | AR34: =AP34-AQ34 -> 2 | AT34: =AR34-AS34 -> 2 | AU34: 2
A35: 33 | B35: RTTO7206 | C35: แร็ค TOYOTA RAV4 VANGUARD ACA3# GSA33 ปี 2005-2015 | L35: =SUM(H35:K35) -> 0 | N35: =L35 -> 0 | P35: =N35-O35 -> 0 | R35: =P35-Q35 -> 0 | T35: =R35-S35 -> 0 | V35: =T35+U35 -> 0 | X35: =V35-W35 -> 0 | Z35: =X35-Y35 -> 0 | AB35: =Z35-AA35 -> 0 | AD35: =AB35-AC35 -> 0 | AF35: =AD35-AE35 -> 0 | AH35: =AF35-AG35 -> 0 | AJ35: =AH35-AI35 -> 0 | AL35: =AJ35-AK35 -> 0 | AN35: =AL35-AM35 -> 0 | AP35: =AN35-AO35 -> 0 | AR35: =AP35-AQ35 -> 0 | AT35: =AR35-AS35 -> 0 | AU35: 0
A36: 34 | B36: RTTO5218 | C36: แร็ค TOYOTA CORONA EXSIOR AT190 ST191 ปี 1992-1998 | H36: 2 | L36: =SUM(H36:K36) -> 2 | N36: =L36 -> 2 | P36: =N36-O36 -> 2 | R36: =P36-Q36 -> 2 | T36: =R36-S36 -> 2 | V36: =T36+U36 -> 2 | X36: =V36-W36 -> 2 | Z36: =X36-Y36 -> 2 | AB36: =Z36-AA36 -> 2 | AD36: =AB36-AC36 -> 2 | AF36: =AD36-AE36 -> 2 | AH36: =AF36-AG36 -> 2 | AJ36: =AH36-AI36 -> 2 | AL36: =AJ36-AK36 -> 2 | AN36: =AL36-AM36 -> 2 | AP36: =AN36-AO36 -> 2 | AR36: =AP36-AQ36 -> 2 | AT36: =AR36-AS36 -> 2 | AU36: 2
A37: 35 | B37: RTTO5236 | C37: แร็ค LEXUS RX300 MCU10 MCU15 TOYOTA HARRIER G1 ปี 1997-2003 | L37: =SUM(H37:K37) -> 0 | N37: =L37 -> 0 | P37: =N37-O37 -> 0 | R37: =P37-Q37 -> 0 | T37: =R37-S37 -> 0 | V37: =T37+U37 -> 0 | X37: =V37-W37 -> 0 | Z37: =X37-Y37 -> 0 | AB37: =Z37-AA37 -> 0 | AD37: =AB37-AC37 -> 0 | AF37: =AD37-AE37 -> 0 | AH37: =AF37-AG37 -> 0 | AJ37: =AH37-AI37 -> 0 | AL37: =AJ37-AK37 -> 0 | AN37: =AL37-AM37 -> 0 | AP37: =AN37-AO37 -> 0 | AR37: =AP37-AQ37 -> 0 | AT37: =AR37-AS37 -> 0 | AU37: 0
